Workbook
Name lst_Team: OFFSET(LISTS!$A$5,0,0,MAX(1,COUNTA(LISTS!$A$5:$A$24)),1)
Name lst_Channel: OFFSET(LISTS!$C$5,0,0,MAX(1,COUNTA(LISTS!$C$5:$C$34)),1)
Name lst_CStatus: OFFSET(LISTS!$D$5,0,0,MAX(1,COUNTA(LISTS!$D$5:$D$14)),1)
Name lst_PStatus: OFFSET(LISTS!$E$5,0,0,MAX(1,COUNTA(LISTS!$E$5:$E$14)),1)
Name lst_AStatus: OFFSET(LISTS!$F$5,0,0,MAX(1,COUNTA(LISTS!$F$5:$F$14)),1)
Name lst_FMonth: OFFSET(LISTS!$G$5,0,0,37,1)
Name lst_FClient: OFFSET(LISTS!$H$5,0,0,MAX(1,COUNTIF(LISTS!$H$5:$H$45,"?*")),1)
Name lst_Client: OFFSET(CLIENTS!$A$5,0,0,MAX(1,COUNTA(CLIENTS!$A$5:$A$44)),1)
Name lst_Campaign: OFFSET(CAMPAIGNS!$B$5,0,0,MAX(1,COUNTA(CAMPAIGNS!$B$5:$B$104)),1)
Name fMonth: DASHBOARD!$B$5
Name fClient: DASHBOARD!$E$5
Name ReportDate: DASHBOARD!$H$5
Name mCrit: DASHBOARD!$L$4
Name cCrit: DASHBOARD!$L$5

Sheet HOW TO USE
B1: HOW TO USE - 3 simple steps
B3: STEP 1 - Team | C3: Go to UPDATE STATS. Add one row each time you have new numbers (daily or weekly): pick Date, Client, Campaign, Channel, Your Name, then type only the numbers that apply (emails, leads, spend...). Numbers are for THAT period - not running totals.
B4: STEP 2 - Campaign owners | C4: On CAMPAIGNS keep Status (Planned / Live / Paused / Completed), dates and Leads Target up to date. Leads, MQLs and spend appear on their own.
B5: STEP 3 - Programs (optional) | C5: On PROGRAM STATUS just change the Status when something moves: Not Started / In Progress / Done / Blocked. No daily tasks needed.
B6: Manager | C6: Open DASHBOARD. Pick Month and Client at the top. Everything else updates by itself.
B8: Colours | C8: BLUE = you type or pick. GREY = automatic, do not type. DASHBOARD is locked (no password) so nothing breaks.
B9: Do not | C9: Rename sheets or column headings, or delete columns. If a campaign is renamed, change it everywhere.
B10: New client / campaign / person | C10: Add on CLIENTS, CAMPAIGNS or LISTS (team). They appear in the dropdowns straight away.
B11: Running out of rows? | C11: Copy the last row (blue and grey cells) and paste below it.
B13: Open Rate | C13: Opens / Emails Sent
B14: Click Rate | C14: Clicks / Emails Sent
B15: Cost per Lead | C15: Ad Spend / Leads
B16: Lead > MQL % | C16: MQLs / Leads
... B18: Leads counted twice? | C18: Enter each lead count once - one row per Campaign per period.

Sheet DASHBOARD
B1: DIGITAL MARKETING DASHBOARD
B2: Updates automatically from UPDATE STATS. Nothing to type here except the 3 blue boxes below.
B4: MONTH | E4: CLIENT | H4: AS OF DATE | L4: =IF(B5="All","<>@@",B5) -> <>@@
B5: All | E5: All | H5: =TODAY() -> 46300 | L5: =IF(E5="All","<>@@",E5) -> <>@@
B7: RESULTS (for the Month and Client selected above)
B8: LEADS | D8: HANDRAISERS | F8: MQLs | H8: SQLs | J8: OPPORTUNITIES | L8: LEAD > MQL %
B9: =SUMIFS('UPDATE STATS'!$L$5:$L$1004,'UPDATE STATS'!$T$5:$T$1004,mCrit,'UPDATE STATS'!$B$5:$B$1004,cCrit) -> 0 | D9: =SUMIFS('UPDATE STATS'!$K$5:$K$1004,'UPDATE STATS'!$T$5:$T$1004,mCrit,'UPDATE STATS'!$B$5:$B$1004,cCrit) -> 0 | F9: =SUMIFS('UPDATE STATS'!$M$5:$M$1004,'UPDATE STATS'!$T$5:$T$1004,mCrit,'UPDATE STATS'!$B$5:$B$1004,cCrit) -> 0 | H9: =SUMIFS('UPDATE STATS'!$N$5:$N$1004,'UPDATE STATS'!$T$5:$T$1004,mCrit,'UPDATE STATS'!$B$5:$B$1004,cCrit) -> 0 | J9: =SUMIFS('UPDATE STATS'!$O$5:$O$1004,'UPDATE STATS'!$T$5:$T$1004,mCrit,'UPDATE STATS'!$B$5:$B$1004,cCrit) -> 0 | L9: =IFERROR(SUMIFS('UPDATE STATS'!$M$5:$M$1004,'UPDATE STATS'!$T$5:$T$1004,mCrit,'UPDATE STATS'!$B$5:$B$1004,cCrit)/SUMIFS('UPDATE STATS'!$L$5:$L$1004,'UPDATE STATS'!$T$5:$T$1004,mCrit,'UPDATE STATS'!$B$5:$B$1004,cCrit),"-") -> -
B11: EMAILS SENT | D11: OPEN RATE | F11: CLICK RATE | H11: REPLIES | J11: AD SPEND | L11: COST PER LEAD
B12: =SUMIFS('UPDATE STATS'!$F$5:$F$1004,'UPDATE STATS'!$T$5:$T$1004,mCrit,'UPDATE STATS'!$B$5:$B$1004,cCrit) -> 0 | D12: =IFERROR(SUMIFS('UPDATE STATS'!$G$5:$G$1004,'UPDATE STATS'!$T$5:$T$1004,mCrit,'UPDATE STATS'!$B$5:$B$1004,cCrit)/SUMIFS('UPDATE STATS'!$F$5:$F$1004,'UPDATE STATS'!$T$5:$T$1004,mCrit,'UPDATE STATS'!$B$5:$B$1004,cCrit),"-") -> - | F12: =IFERROR(SUMIFS('UPDATE STATS'!$H$5:$H$1004,'UPDATE STATS'!$T$5:$T$1004,mCrit,'UPDATE STATS'!$B$5:$B$1004,cCrit)/SUMIFS('UPDATE STATS'!$F$5:$F$1004,'UPDATE STATS'!$T$5:$T$1004,mCrit,'UPDATE STATS'!$B$5:$B$1004,cCrit),"-") -> - | H12: =SUMIFS('UPDATE STATS'!$I$5:$I$1004,'UPDATE STATS'!$T$5:$T$1004,mCrit,'UPDATE STATS'!$B$5:$B$1004,cCrit) -> 0 | J12: =SUMIFS('UPDATE STATS'!$J$5:$J$1004,'UPDATE STATS'!$T$5:$T$1004,mCrit,'UPDATE STATS'!$B$5:$B$1004,cCrit) -> 0 | L12: =IFERROR(SUMIFS('UPDATE STATS'!$J$5:$J$1004,'UPDATE STATS'!$T$5:$T$1004,mCrit,'UPDATE STATS'!$B$5:$B$1004,cCrit)/SUMIFS('UPDATE STATS'!$L$5:$L$1004,'UPDATE STATS'!$T$5:$T$1004,mCrit,'UPDATE STATS'!$B$5:$B$1004,cCrit),"-") -> -
B14: NEEDS ATTENTION
B15: LIVE CAMPAIGNS | D15: NEED A STATS UPDATE | F15: BEHIND TARGET | H15: PROGRAMS BLOCKED | J15: STATUS NOT UPDATED | L15: PROGRAMS DONE
B16: =COUNTIFS('CAMPAIGNS'!$E$5:$E$604,"Live") -> 0 | D16: =COUNTIFS('CAMPAIGNS'!$O$5:$O$604,"Update needed")+COUNTIFS('CAMPAIGNS'!$O$5:$O$604,"No stats yet") -> 0 | F16: =COUNTIFS('CAMPAIGNS'!$O$5:$O$604,"Behind target") -> 0 | H16: =COUNTIFS('PROGRAM STATUS'!$E$5:$E$654,"Blocked") -> 0 | J16: =COUNTIFS('PROGRAM STATUS'!$C$5:$C$654,"<>")-COUNTIFS('PROGRAM STATUS'!$E$5:$E$654,"<>") -> 58 | L16: =COUNTIFS('PROGRAM STATUS'!$E$5:$E$654,"Done") -> 0
B18: Blocked programs | F18: Client | H18: Team Member | J18: Remark / Next Step
B19: =IFERROR(IF(INDEX('PROGRAM STATUS'!$C$5:$C$654,MATCH(SMALL('PROGRAM STATUS'!$H$5:$H$654,1),'PROGRAM STATUS'!$H$5:$H$654,0))="","",INDEX('PROGRAM STATUS'!$C$5:$C$654,MATCH(SMALL('PROGRAM STATUS'!$H$5:$H$654,1),'PROGRAM STATUS'!$H$5:$H$654,0))),"- none -") -> - none - | F19: =IFERROR(IF(INDEX('PROGRAM STATUS'!$B$5:$B$654,MATCH(SMALL('PROGRAM STATUS'!$H$5:$H$654,1),'PROGRAM STATUS'!$H$5:$H$654,0))="","",INDEX('PROGRAM STATUS'!$B$5:$B$654,MATCH(SMALL('PROGRAM STATUS'!$H$5:$H$654,1),'PROGRAM STATUS'!$H$5:$H$654,0))),"") | H19: =IFERROR(IF(INDEX('PROGRAM STATUS'!$A$5:$A$654,MATCH(SMALL('PROGRAM STATUS'!$H$5:$H$654,1),'PROGRAM STATUS'!$H$5:$H$654,0))="","",INDEX('PROGRAM STATUS'!$A$5:$A$654,MATCH(SMALL('PROGRAM STATUS'!$H$5:$H$654,1),'PROGRAM STATUS'!$H$5:$H$654,0))),"") | J19: =IFERROR(IF(INDEX('PROGRAM STATUS'!$G$5:$G$654,MATCH(SMALL('PROGRAM STATUS'!$H$5:$H$654,1),'PROGRAM STATUS'!$H$5:$H$654,0))="","",INDEX('PROGRAM STATUS'!$G$5:$G$654,MATCH(SMALL('PROGRAM STATUS'!$H$5:$H$654,1),'PROGRAM STATUS'!$H$5:$H$654,0))),"")
B20: =IFERROR(IF(INDEX('PROGRAM STATUS'!$C$5:$C$654,MATCH(SMALL('PROGRAM STATUS'!$H$5:$H$654,2),'PROGRAM STATUS'!$H$5:$H$654,0))="","",INDEX('PROGRAM STATUS'!$C$5:$C$654,MATCH(SMALL('PROGRAM STATUS'!$H$5:$H$654,2),'PROGRAM STATUS'!$H$5:$H$654,0))),"") | F20: =IFERROR(IF(INDEX('PROGRAM STATUS'!$B$5:$B$654,MATCH(SMALL('PROGRAM STATUS'!$H$5:$H$654,2),'PROGRAM STATUS'!$H$5:$H$654,0))="","",INDEX('PROGRAM STATUS'!$B$5:$B$654,MATCH(SMALL('PROGRAM STATUS'!$H$5:$H$654,2),'PROGRAM STATUS'!$H$5:$H$654,0))),"") | H20: =IFERROR(IF(INDEX('PROGRAM STATUS'!$A$5:$A$654,MATCH(SMALL('PROGRAM STATUS'!$H$5:$H$654,2),'PROGRAM STATUS'!$H$5:$H$654,0))="","",INDEX('PROGRAM STATUS'!$A$5:$A$654,MATCH(SMALL('PROGRAM STATUS'!$H$5:$H$654,2),'PROGRAM STATUS'!$H$5:$H$654,0))),"") | J20: =IFERROR(IF(INDEX('PROGRAM STATUS'!$G$5:$G$654,MATCH(SMALL('PROGRAM STATUS'!$H$5:$H$654,2),'PROGRAM STATUS'!$H$5:$H$654,0))="","",INDEX('PROGRAM STATUS'!$G$5:$G$654,MATCH(SMALL('PROGRAM STATUS'!$H$5:$H$654,2),'PROGRAM STATUS'!$H$5:$H$654,0))),"")
B21: =IFERROR(IF(INDEX('PROGRAM STATUS'!$C$5:$C$654,MATCH(SMALL('PROGRAM STATUS'!$H$5:$H$654,3),'PROGRAM STATUS'!$H$5:$H$654,0))="","",INDEX('PROGRAM STATUS'!$C$5:$C$654,MATCH(SMALL('PROGRAM STATUS'!$H$5:$H$654,3),'PROGRAM STATUS'!$H$5:$H$654,0))),"") | F21: =IFERROR(IF(INDEX('PROGRAM STATUS'!$B$5:$B$654,MATCH(SMALL('PROGRAM STATUS'!$H$5:$H$654,3),'PROGRAM STATUS'!$H$5:$H$654,0))="","",INDEX('PROGRAM STATUS'!$B$5:$B$654,MATCH(SMALL('PROGRAM STATUS'!$H$5:$H$654,3),'PROGRAM STATUS'!$H$5:$H$654,0))),"") | H21: =IFERROR(IF(INDEX('PROGRAM STATUS'!$A$5:$A$654,MATCH(SMALL('PROGRAM STATUS'!$H$5:$H$654,3),'PROGRAM STATUS'!$H$5:$H$654,0))="","",INDEX('PROGRAM STATUS'!$A$5:$A$654,MATCH(SMALL('PROGRAM STATUS'!$H$5:$H$654,3),'PROGRAM STATUS'!$H$5:$H$654,0))),"") | J21: =IFERROR(IF(INDEX('PROGRAM STATUS'!$G$5:$G$654,MATCH(SMALL('PROGRAM STATUS'!$H$5:$H$654,3),'PROGRAM STATUS'!$H$5:$H$654,0))="","",INDEX('PROGRAM STATUS'!$G$5:$G$654,MATCH(SMALL('PROGRAM STATUS'!$H$5:$H$654,3),'PROGRAM STATUS'!$H$5:$H$654,0))),"")
B22: =IFERROR(IF(INDEX('PROGRAM STATUS'!$C$5:$C$654,MATCH(SMALL('PROGRAM STATUS'!$H$5:$H$654,4),'PROGRAM STATUS'!$H$5:$H$654,0))="","",INDEX('PROGRAM STATUS'!$C$5:$C$654,MATCH(SMALL('PROGRAM STATUS'!$H$5:$H$654,4),'PROGRAM STATUS'!$H$5:$H$654,0))),"") | F22: =IFERROR(IF(INDEX('PROGRAM STATUS'!$B$5:$B$654,MATCH(SMALL('PROGRAM STATUS'!$H$5:$H$654,4),'PROGRAM STATUS'!$H$5:$H$654,0))="","",INDEX('PROGRAM STATUS'!$B$5:$B$654,MATCH(SMALL('PROGRAM STATUS'!$H$5:$H$654,4),'PROGRAM STATUS'!$H$5:$H$654,0))),"") | H22: =IFERROR(IF(INDEX('PROGRAM STATUS'!$A$5:$A$654,MATCH(SMALL('PROGRAM STATUS'!$H$5:$H$654,4),'PROGRAM STATUS'!$H$5:$H$654,0))="","",INDEX('PROGRAM STATUS'!$A$5:$A$654,MATCH(SMALL('PROGRAM STATUS'!$H$5:$H$654,4),'PROGRAM STATUS'!$H$5:$H$654,0))),"") | J22: =IFERROR(IF(INDEX('PROGRAM STATUS'!$G$5:$G$654,MATCH(SMALL('PROGRAM STATUS'!$H$5:$H$654,4),'PROGRAM STATUS'!$H$5:$H$654,0))="","",INDEX('PROGRAM STATUS'!$G$5:$G$654,MATCH(SMALL('PROGRAM STATUS'!$H$5:$H$654,4),'PROGRAM STATUS'!$H$5:$H$654,0))),"")
B23: =IFERROR(IF(INDEX('PROGRAM STATUS'!$C$5:$C$654,MATCH(SMALL('PROGRAM STATUS'!$H$5:$H$654,5),'PROGRAM STATUS'!$H$5:$H$654,0))="","",INDEX('PROGRAM STATUS'!$C$5:$C$654,MATCH(SMALL('PROGRAM STATUS'!$H$5:$H$654,5),'PROGRAM STATUS'!$H$5:$H$654,0))),"") | F23: =IFERROR(IF(INDEX('PROGRAM STATUS'!$B$5:$B$654,MATCH(SMALL('PROGRAM STATUS'!$H$5:$H$654,5),'PROGRAM STATUS'!$H$5:$H$654,0))="","",INDEX('PROGRAM STATUS'!$B$5:$B$654,MATCH(SMALL('PROGRAM STATUS'!$H$5:$H$654,5),'PROGRAM STATUS'!$H$5:$H$654,0))),"") | H23: =IFERROR(IF(INDEX('PROGRAM STATUS'!$A$5:$A$654,MATCH(SMALL('PROGRAM STATUS'!$H$5:$H$654,5),'PROGRAM STATUS'!$H$5:$H$654,0))="","",INDEX('PROGRAM STATUS'!$A$5:$A$654,MATCH(SMALL('PROGRAM STATUS'!$H$5:$H$654,5),'PROGRAM STATUS'!$H$5:$H$654,0))),"") | J23: =IFERROR(IF(INDEX('PROGRAM STATUS'!$G$5:$G$654,MATCH(SMALL('PROGRAM STATUS'!$H$5:$H$654,5),'PROGRAM STATUS'!$H$5:$H$654,0))="","",INDEX('PROGRAM STATUS'!$G$5:$G$654,MATCH(SMALL('PROGRAM STATUS'!$H$5:$H$654,5),'PROGRAM STATUS'!$H$5:$H$654,0))),"")
B25: BY CLIENT (Month filter applies) - Tata Communications / MECCA highlighted
B26: Client | D26: Status | E26: Leads | F26: MQLs | G26: SQLs | H26: Emails Sent | I26: Open Rate | J26: Ad Spend | K26: Cost / Lead | L26: Programs Blocked
B27: =IF(CLIENTS!A5="","",CLIENTS!A5) -> Chola MS | D27: =IF($B27="","",IF(CLIENTS!B5="","",CLIENTS!B5)) -> Active | E27: =IF($B27="","",SUMIFS('UPDATE STATS'!$L$5:$L$1004,'UPDATE STATS'!$B$5:$B$1004,$B27,'UPDATE STATS'!$T$5:$T$1004,mCrit)) -> 0 | F27: =IF($B27="","",SUMIFS('UPDATE STATS'!$M$5:$M$1004,'UPDATE STATS'!$B$5:$B$1004,$B27,'UPDATE STATS'!$T$5:$T$1004,mCrit)) -> 0 | G27: =IF($B27="","",SUMIFS('UPDATE STATS'!$N$5:$N$1004,'UPDATE STATS'!$B$5:$B$1004,$B27,'UPDATE STATS'!$T$5:$T$1004,mCrit)) -> 0 | H27: =IF($B27="","",SUMIFS('UPDATE STATS'!$F$5:$F$1004,'UPDATE STATS'!$B$5:$B$1004,$B27,'UPDATE STATS'!$T$5:$T$1004,mCrit)) -> 0 | I27: =IF($B27="","",IFERROR(SUMIFS('UPDATE STATS'!$G$5:$G$1004,'UPDATE STATS'!$B$5:$B$1004,$B27,'UPDATE STATS'!$T$5:$T$1004,mCrit)/SUMIFS('UPDATE STATS'!$F$5:$F$1004,'UPDATE STATS'!$B$5:$B$1004,$B27,'UPDATE STATS'!$T$5:$T$1004,mCrit),"")) | J27: =IF($B27="","",SUMIFS('UPDATE STATS'!$J$5:$J$1004,'UPDATE STATS'!$B$5:$B$1004,$B27,'UPDATE STATS'!$T$5:$T$1004,mCrit)) -> 0 | K27: =IF($B27="","",IF(SUMIFS('UPDATE STATS'!$J$5:$J$1004,'UPDATE STATS'!$B$5:$B$1004,$B27,'UPDATE STATS'!$T$5:$T$1004,mCrit)>0,IFERROR(SUMIFS('UPDATE STATS'!$J$5:$J$1004,'UPDATE STATS'!$B$5:$B$1004,$B27,'UPDATE STATS'!$T$5:$T$1004,mCrit)/SUMIFS('UPDATE STATS'!$L$5:$L$1004,'UPDATE STATS'!$B$5:$B$1004,$B27,'UPDATE STATS'!$T$5:$T$1004,mCrit),""),"")) | L27: =IF($B27="","",COUNTIFS('PROGRAM STATUS'!$B$5:$B$654,$B27,'PROGRAM STATUS'!$E$5:$E$654,"Blocked")) -> 0
B28: =IF(CLIENTS!A6="","",CLIENTS!A6) -> Magnasoft | D28: =IF($B28="","",IF(CLIENTS!B6="","",CLIENTS!B6)) -> Active | E28: =IF($B28="","",SUMIFS('UPDATE STATS'!$L$5:$L$1004,'UPDATE STATS'!$B$5:$B$1004,$B28,'UPDATE STATS'!$T$5:$T$1004,mCrit)) -> 0 | F28: =IF($B28="","",SUMIFS('UPDATE STATS'!$M$5:$M$1004,'UPDATE STATS'!$B$5:$B$1004,$B28,'UPDATE STATS'!$T$5:$T$1004,mCrit)) -> 0 | G28: =IF($B28="","",SUMIFS('UPDATE STATS'!$N$5:$N$1004,'UPDATE STATS'!$B$5:$B$1004,$B28,'UPDATE STATS'!$T$5:$T$1004,mCrit)) -> 0 | H28: =IF($B28="","",SUMIFS('UPDATE STATS'!$F$5:$F$1004,'UPDATE STATS'!$B$5:$B$1004,$B28,'UPDATE STATS'!$T$5:$T$1004,mCrit)) -> 0 | I28: =IF($B28="","",IFERROR(SUMIFS('UPDATE STATS'!$G$5:$G$1004,'UPDATE STATS'!$B$5:$B$1004,$B28,'UPDATE STATS'!$T$5:$T$1004,mCrit)/SUMIFS('UPDATE STATS'!$F$5:$F$1004,'UPDATE STATS'!$B$5:$B$1004,$B28,'UPDATE STATS'!$T$5:$T$1004,mCrit),"")) | J28: =IF($B28="","",SUMIFS('UPDATE STATS'!$J$5:$J$1004,'UPDATE STATS'!$B$5:$B$1004,$B28,'UPDATE STATS'!$T$5:$T$1004,mCrit)) -> 0 | K28: =IF($B28="","",IF(SUMIFS('UPDATE STATS'!$J$5:$J$1004,'UPDATE STATS'!$B$5:$B$1004,$B28,'UPDATE STATS'!$T$5:$T$1004,mCrit)>0,IFERROR(SUMIFS('UPDATE STATS'!$J$5:$J$1004,'UPDATE STATS'!$B$5:$B$1004,$B28,'UPDATE STATS'!$T$5:$T$1004,mCrit)/SUMIFS('UPDATE STATS'!$L$5:$L$1004,'UPDATE STATS'!$B$5:$B$1004,$B28,'UPDATE STATS'!$T$5:$T$1004,mCrit),""),"")) | L28: =IF($B28="","",COUNTIFS('PROGRAM STATUS'!$B$5:$B$654,$B28,'PROGRAM STATUS'!$E$5:$E$654,"Blocked")) -> 0
B29: =IF(CLIENTS!A7="","",CLIENTS!A7) -> Eternelle | D29: =IF($B29="","",IF(CLIENTS!B7="","",CLIENTS!B7)) -> Active | E29: =IF($B29="","",SUMIFS('UPDATE STATS'!$L$5:$L$1004,'UPDATE STATS'!$B$5:$B$1004,$B29,'UPDATE STATS'!$T$5:$T$1004,mCrit)) -> 0 | F29: =IF($B29="","",SUMIFS('UPDATE STATS'!$M$5:$M$1004,'UPDATE STATS'!$B$5:$B$1004,$B29,'UPDATE STATS'!$T$5:$T$1004,mCrit)) -> 0 | G29: =IF($B29="","",SUMIFS('UPDATE STATS'!$N$5:$N$1004,'UPDATE STATS'!$B$5:$B$1004,$B29,'UPDATE STATS'!$T$5:$T$1004,mCrit)) -> 0 | H29: =IF($B29="","",SUMIFS('UPDATE STATS'!$F$5:$F$1004,'UPDATE STATS'!$B$5:$B$1004,$B29,'UPDATE STATS'!$T$5:$T$1004,mCrit)) -> 0 | I29: =IF($B29="","",IFERROR(SUMIFS('UPDATE STATS'!$G$5:$G$1004,'UPDATE STATS'!$B$5:$B$1004,$B29,'UPDATE STATS'!$T$5:$T$1004,mCrit)/SUMIFS('UPDATE STATS'!$F$5:$F$1004,'UPDATE STATS'!$B$5:$B$1004,$B29,'UPDATE STATS'!$T$5:$T$1004,mCrit),"")) | J29: =IF($B29="","",SUMIFS('UPDATE STATS'!$J$5:$J$1004,'UPDATE STATS'!$B$5:$B$1004,$B29,'UPDATE STATS'!$T$5:$T$1004,mCrit)) -> 0 | K29: =IF($B29="","",IF(SUMIFS('UPDATE STATS'!$J$5:$J$1004,'UPDATE STATS'!$B$5:$B$1004,$B29,'UPDATE STATS'!$T$5:$T$1004,mCrit)>0,IFERROR(SUMIFS('UPDATE STATS'!$J$5:$J$1004,'UPDATE STATS'!$B$5:$B$1004,$B29,'UPDATE STATS'!$T$5:$T$1004,mCrit)/SUMIFS('UPDATE STATS'!$L$5:$L$1004,'UPDATE STATS'!$B$5:$B$1004,$B29,'UPDATE STATS'!$T$5:$T$1004,mCrit),""),"")) | L29: =IF($B29="","",COUNTIFS('PROGRAM STATUS'!$B$5:$B$654,$B29,'PROGRAM STATUS'!$E$5:$E$654,"Blocked")) -> 0
B30: =IF(CLIENTS!A8="","",CLIENTS!A8) -> Vestrics | D30: =IF($B30="","",IF(CLIENTS!B8="","",CLIENTS!B8)) -> Active | E30: =IF($B30="","",SUMIFS('UPDATE STATS'!$L$5:$L$1004,'UPDATE STATS'!$B$5:$B$1004,$B30,'UPDATE STATS'!$T$5:$T$1004,mCrit)) -> 0 | F30: =IF($B30="","",SUMIFS('UPDATE STATS'!$M$5:$M$1004,'UPDATE STATS'!$B$5:$B$1004,$B30,'UPDATE STATS'!$T$5:$T$1004,mCrit)) -> 0 | G30: =IF($B30="","",SUMIFS('UPDATE STATS'!$N$5:$N$1004,'UPDATE STATS'!$B$5:$B$1004,$B30,'UPDATE STATS'!$T$5:$T$1004,mCrit)) -> 0 | H30: =IF($B30="","",SUMIFS('UPDATE STATS'!$F$5:$F$1004,'UPDATE STATS'!$B$5:$B$1004,$B30,'UPDATE STATS'!$T$5:$T$1004,mCrit)) -> 0 | I30: =IF($B30="","",IFERROR(SUMIFS('UPDATE STATS'!$G$5:$G$1004,'UPDATE STATS'!$B$5:$B$1004,$B30,'UPDATE STATS'!$T$5:$T$1004,mCrit)/SUMIFS('UPDATE STATS'!$F$5:$F$1004,'UPDATE STATS'!$B$5:$B$1004,$B30,'UPDATE STATS'!$T$5:$T$1004,mCrit),"")) | J30: =IF($B30="","",SUMIFS('UPDATE STATS'!$J$5:$J$1004,'UPDATE STATS'!$B$5:$B$1004,$B30,'UPDATE STATS'!$T$5:$T$1004,mCrit)) -> 0 | K30: =IF($B30="","",IF(SUMIFS('UPDATE STATS'!$J$5:$J$1004,'UPDATE STATS'!$B$5:$B$1004,$B30,'UPDATE STATS'!$T$5:$T$1004,mCrit)>0,IFERROR(SUMIFS('UPDATE STATS'!$J$5:$J$1004,'UPDATE STATS'!$B$5:$B$1004,$B30,'UPDATE STATS'!$T$5:$T$1004,mCrit)/SUMIFS('UPDATE STATS'!$L$5:$L$1004,'UPDATE STATS'!$B$5:$B$1004,$B30,'UPDATE STATS'!$T$5:$T$1004,mCrit),""),"")) | L30: =IF($B30="","",COUNTIFS('PROGRAM STATUS'!$B$5:$B$654,$B30,'PROGRAM STATUS'!$E$5:$E$654,"Blocked")) -> 0
B31: =IF(CLIENTS!A9="","",CLIENTS!A9) -> Lenovo | D31: =IF($B31="","",IF(CLIENTS!B9="","",CLIENTS!B9)) -> Active | E31: =IF($B31="","",SUMIFS('UPDATE STATS'!$L$5:$L$1004,'UPDATE STATS'!$B$5:$B$1004,$B31,'UPDATE STATS'!$T$5:$T$1004,mCrit)) -> 0 | F31: =IF($B31="","",SUMIFS('UPDATE STATS'!$M$5:$M$1004,'UPDATE STATS'!$B$5:$B$1004,$B31,'UPDATE STATS'!$T$5:$T$1004,mCrit)) -> 0 | G31: =IF($B31="","",SUMIFS('UPDATE STATS'!$N$5:$N$1004,'UPDATE STATS'!$B$5:$B$1004,$B31,'UPDATE STATS'!$T$5:$T$1004,mCrit)) -> 0 | H31: =IF($B31="","",SUMIFS('UPDATE STATS'!$F$5:$F$1004,'UPDATE STATS'!$B$5:$B$1004,$B31,'UPDATE STATS'!$T$5:$T$1004,mCrit)) -> 0 | I31: =IF($B31="","",IFERROR(SUMIFS('UPDATE STATS'!$G$5:$G$1004,'UPDATE STATS'!$B$5:$B$1004,$B31,'UPDATE STATS'!$T$5:$T$1004,mCrit)/SUMIFS('UPDATE STATS'!$F$5:$F$1004,'UPDATE STATS'!$B$5:$B$1004,$B31,'UPDATE STATS'!$T$5:$T$1004,mCrit),"")) | J31: =IF($B31="","",SUMIFS('UPDATE STATS'!$J$5:$J$1004,'UPDATE STATS'!$B$5:$B$1004,$B31,'UPDATE STATS'!$T$5:$T$1004,mCrit)) -> 0 | K31: =IF($B31="","",IF(SUMIFS('UPDATE STATS'!$J$5:$J$1004,'UPDATE STATS'!$B$5:$B$1004,$B31,'UPDATE STATS'!$T$5:$T$1004,mCrit)>0,IFERROR(SUMIFS('UPDATE STATS'!$J$5:$J$1004,'UPDATE STATS'!$B$5:$B$1004,$B31,'UPDATE STATS'!$T$5:$T$1004,mCrit)/SUMIFS('UPDATE STATS'!$L$5:$L$1004,'UPDATE STATS'!$B$5:$B$1004,$B31,'UPDATE STATS'!$T$5:$T$1004,mCrit),""),"")) | L31: =IF($B31="","",COUNTIFS('PROGRAM STATUS'!$B$5:$B$654,$B31,'PROGRAM STATUS'!$E$5:$E$654,"Blocked")) -> 0
B32: =IF(CLIENTS!A10="","",CLIENTS!A10) -> SAP | D32: =IF($B32="","",IF(CLIENTS!B10="","",CLIENTS!B10)) -> Active | E32: =IF($B32="","",SUMIFS('UPDATE STATS'!$L$5:$L$1004,'UPDATE STATS'!$B$5:$B$1004,$B32,'UPDATE STATS'!$T$5:$T$1004,mCrit)) -> 0 | F32: =IF($B32="","",SUMIFS('UPDATE STATS'!$M$5:$M$1004,'UPDATE STATS'!$B$5:$B$1004,$B32,'UPDATE STATS'!$T$5:$T$1004,mCrit)) -> 0 | G32: =IF($B32="","",SUMIFS('UPDATE STATS'!$N$5:$N$1004,'UPDATE STATS'!$B$5:$B$1004,$B32,'UPDATE STATS'!$T$5:$T$1004,mCrit)) -> 0 | H32: =IF($B32="","",SUMIFS('UPDATE STATS'!$F$5:$F$1004,'UPDATE STATS'!$B$5:$B$1004,$B32,'UPDATE STATS'!$T$5:$T$1004,mCrit)) -> 0 | I32: =IF($B32="","",IFERROR(SUMIFS('UPDATE STATS'!$G$5:$G$1004,'UPDATE STATS'!$B$5:$B$1004,$B32,'UPDATE STATS'!$T$5:$T$1004,mCrit)/SUMIFS('UPDATE STATS'!$F$5:$F$1004,'UPDATE STATS'!$B$5:$B$1004,$B32,'UPDATE STATS'!$T$5:$T$1004,mCrit),"")) | J32: =IF($B32="","",SUMIFS('UPDATE STATS'!$J$5:$J$1004,'UPDATE STATS'!$B$5:$B$1004,$B32,'UPDATE STATS'!$T$5:$T$1004,mCrit)) -> 0 | K32: =IF($B32="","",IF(SUMIFS('UPDATE STATS'!$J$5:$J$1004,'UPDATE STATS'!$B$5:$B$1004,$B32,'UPDATE STATS'!$T$5:$T$1004,mCrit)>0,IFERROR(SUMIFS('UPDATE STATS'!$J$5:$J$1004,'UPDATE STATS'!$B$5:$B$1004,$B32,'UPDATE STATS'!$T$5:$T$1004,mCrit)/SUMIFS('UPDATE STATS'!$L$5:$L$1004,'UPDATE STATS'!$B$5:$B$1004,$B32,'UPDATE STATS'!$T$5:$T$1004,mCrit),""),"")) | L32: =IF($B32="","",COUNTIFS('PROGRAM STATUS'!$B$5:$B$654,$B32,'PROGRAM STATUS'!$E$5:$E$654,"Blocked")) -> 0
B33: =IF(CLIENTS!A11="","",CLIENTS!A11) -> Tata Communications | D33: =IF($B33="","",IF(CLIENTS!B11="","",CLIENTS!B11)) -> Active | E33: =IF($B33="","",SUMIFS('UPDATE STATS'!$L$5:$L$1004,'UPDATE STATS'!$B$5:$B$1004,$B33,'UPDATE STATS'!$T$5:$T$1004,mCrit)) -> 0 | F33: =IF($B33="","",SUMIFS('UPDATE STATS'!$M$5:$M$1004,'UPDATE STATS'!$B$5:$B$1004,$B33,'UPDATE STATS'!$T$5:$T$1004,mCrit)) -> 0 | G33: =IF($B33="","",SUMIFS('UPDATE STATS'!$N$5:$N$1004,'UPDATE STATS'!$B$5:$B$1004,$B33,'UPDATE STATS'!$T$5:$T$1004,mCrit)) -> 0 | H33: =IF($B33="","",SUMIFS('UPDATE STATS'!$F$5:$F$1004,'UPDATE STATS'!$B$5:$B$1004,$B33,'UPDATE STATS'!$T$5:$T$1004,mCrit)) -> 0 | I33: =IF($B33="","",IFERROR(SUMIFS('UPDATE STATS'!$G$5:$G$1004,'UPDATE STATS'!$B$5:$B$1004,$B33,'UPDATE STATS'!$T$5:$T$1004,mCrit)/SUMIFS('UPDATE STATS'!$F$5:$F$1004,'UPDATE STATS'!$B$5:$B$1004,$B33,'UPDATE STATS'!$T$5:$T$1004,mCrit),"")) | J33: =IF($B33="","",SUMIFS('UPDATE STATS'!$J$5:$J$1004,'UPDATE STATS'!$B$5:$B$1004,$B33,'UPDATE STATS'!$T$5:$T$1004,mCrit)) -> 0 | K33: =IF($B33="","",IF(SUMIFS('UPDATE STATS'!$J$5:$J$1004,'UPDATE STATS'!$B$5:$B$1004,$B33,'UPDATE STATS'!$T$5:$T$1004,mCrit)>0,IFERROR(SUMIFS('UPDATE STATS'!$J$5:$J$1004,'UPDATE STATS'!$B$5:$B$1004,$B33,'UPDATE STATS'!$T$5:$T$1004,mCrit)/SUMIFS('UPDATE STATS'!$L$5:$L$1004,'UPDATE STATS'!$B$5:$B$1004,$B33,'UPDATE STATS'!$T$5:$T$1004,mCrit),""),"")) | L33: =IF($B33="","",COUNTIFS('PROGRAM STATUS'!$B$5:$B$654,$B33,'PROGRAM STATUS'!$E$5:$E$654,"Blocked")) -> 0
B34: =IF(CLIENTS!A12="","",CLIENTS!A12) -> Tata Communications MECCA | D34: =IF($B34="","",IF(CLIENTS!B12="","",CLIENTS!B12)) -> Active | E34: =IF($B34="","",SUMIFS('UPDATE STATS'!$L$5:$L$1004,'UPDATE STATS'!$B$5:$B$1004,$B34,'UPDATE STATS'!$T$5:$T$1004,mCrit)) -> 0 | F34: =IF($B34="","",SUMIFS('UPDATE STATS'!$M$5:$M$1004,'UPDATE STATS'!$B$5:$B$1004,$B34,'UPDATE STATS'!$T$5:$T$1004,mCrit)) -> 0 | G34: =IF($B34="","",SUMIFS('UPDATE STATS'!$N$5:$N$1004,'UPDATE STATS'!$B$5:$B$1004,$B34,'UPDATE STATS'!$T$5:$T$1004,mCrit)) -> 0 | H34: =IF($B34="","",SUMIFS('UPDATE STATS'!$F$5:$F$1004,'UPDATE STATS'!$B$5:$B$1004,$B34,'UPDATE STATS'!$T$5:$T$1004,mCrit)) -> 0 | I34: =IF($B34="","",IFERROR(SUMIFS('UPDATE STATS'!$G$5:$G$1004,'UPDATE STATS'!$B$5:$B$1004,$B34,'UPDATE STATS'!$T$5:$T$1004,mCrit)/SUMIFS('UPDATE STATS'!$F$5:$F$1004,'UPDATE STATS'!$B$5:$B$1004,$B34,'UPDATE STATS'!$T$5:$T$1004,mCrit),"")) | J34: =IF($B34="","",SUMIFS('UPDATE STATS'!$J$5:$J$1004,'UPDATE STATS'!$B$5:$B$1004,$B34,'UPDATE STATS'!$T$5:$T$1004,mCrit)) -> 0 | K34: =IF($B34="","",IF(SUMIFS('UPDATE STATS'!$J$5:$J$1004,'UPDATE STATS'!$B$5:$B$1004,$B34,'UPDATE STATS'!$T$5:$T$1004,mCrit)>0,IFERROR(SUMIFS('UPDATE STATS'!$J$5:$J$1004,'UPDATE STATS'!$B$5:$B$1004,$B34,'UPDATE STATS'!$T$5:$T$1004,mCrit)/SUMIFS('UPDATE STATS'!$L$5:$L$1004,'UPDATE STATS'!$B$5:$B$1004,$B34,'UPDATE STATS'!$T$5:$T$1004,mCrit),""),"")) | L34: =IF($B34="","",COUNTIFS('PROGRAM STATUS'!$B$5:$B$654,$B34,'PROGRAM STATUS'!$E$5:$E$654,"Blocked")) -> 0
B35: =IF(CLIENTS!A13="","",CLIENTS!A13) -> Salesforce | D35: =IF($B35="","",IF(CLIENTS!B13="","",CLIENTS!B13)) -> Active | E35: =IF($B35="","",SUMIFS('UPDATE STATS'!$L$5:$L$1004,'UPDATE STATS'!$B$5:$B$1004,$B35,'UPDATE STATS'!$T$5:$T$1004,mCrit)) -> 0 | F35: =IF($B35="","",SUMIFS('UPDATE STATS'!$M$5:$M$1004,'UPDATE STATS'!$B$5:$B$1004,$B35,'UPDATE STATS'!$T$5:$T$1004,mCrit)) -> 0 | G35: =IF($B35="","",SUMIFS('UPDATE STATS'!$N$5:$N$1004,'UPDATE STATS'!$B$5:$B$1004,$B35,'UPDATE STATS'!$T$5:$T$1004,mCrit)) -> 0 | H35: =IF($B35="","",SUMIFS('UPDATE STATS'!$F$5:$F$1004,'UPDATE STATS'!$B$5:$B$1004,$B35,'UPDATE STATS'!$T$5:$T$1004,mCrit)) -> 0 | I35: =IF($B35="","",IFERROR(SUMIFS('UPDATE STATS'!$G$5:$G$1004,'UPDATE STATS'!$B$5:$B$1004,$B35,'UPDATE STATS'!$T$5:$T$1004,mCrit)/SUMIFS('UPDATE STATS'!$F$5:$F$1004,'UPDATE STATS'!$B$5:$B$1004,$B35,'UPDATE STATS'!$T$5:$T$1004,mCrit),"")) | J35: =IF($B35="","",SUMIFS('UPDATE STATS'!$J$5:$J$1004,'UPDATE STATS'!$B$5:$B$1004,$B35,'UPDATE STATS'!$T$5:$T$1004,mCrit)) -> 0 | K35: =IF($B35="","",IF(SUMIFS('UPDATE STATS'!$J$5:$J$1004,'UPDATE STATS'!$B$5:$B$1004,$B35,'UPDATE STATS'!$T$5:$T$1004,mCrit)>0,IFERROR(SUMIFS('UPDATE STATS'!$J$5:$J$1004,'UPDATE STATS'!$B$5:$B$1004,$B35,'UPDATE STATS'!$T$5:$T$1004,mCrit)/SUMIFS('UPDATE STATS'!$L$5:$L$1004,'UPDATE STATS'!$B$5:$B$1004,$B35,'UPDATE STATS'!$T$5:$T$1004,mCrit),""),"")) | L35: =IF($B35="","",COUNTIFS('PROGRAM STATUS'!$B$5:$B$654,$B35,'PROGRAM STATUS'!$E$5:$E$654,"Blocked")) -> 0
B36: =IF(CLIENTS!A14="","",CLIENTS!A14) -> Ruckus Networks | D36: =IF($B36="","",IF(CLIENTS!B14="","",CLIENTS!B14)) -> Active | E36: =IF($B36="","",SUMIFS('UPDATE STATS'!$L$5:$L$1004,'UPDATE STATS'!$B$5:$B$1004,$B36,'UPDATE STATS'!$T$5:$T$1004,mCrit)) -> 0 | F36: =IF($B36="","",SUMIFS('UPDATE STATS'!$M$5:$M$1004,'UPDATE STATS'!$B$5:$B$1004,$B36,'UPDATE STATS'!$T$5:$T$1004,mCrit)) -> 0 | G36: =IF($B36="","",SUMIFS('UPDATE STATS'!$N$5:$N$1004,'UPDATE STATS'!$B$5:$B$1004,$B36,'UPDATE STATS'!$T$5:$T$1004,mCrit)) -> 0 | H36: =IF($B36="","",SUMIFS('UPDATE STATS'!$F$5:$F$1004,'UPDATE STATS'!$B$5:$B$1004,$B36,'UPDATE STATS'!$T$5:$T$1004,mCrit)) -> 0 | I36: =IF($B36="","",IFERROR(SUMIFS('UPDATE STATS'!$G$5:$G$1004,'UPDATE STATS'!$B$5:$B$1004,$B36,'UPDATE STATS'!$T$5:$T$1004,mCrit)/SUMIFS('UPDATE STATS'!$F$5:$F$1004,'UPDATE STATS'!$B$5:$B$1004,$B36,'UPDATE STATS'!$T$5:$T$1004,mCrit),"")) | J36: =IF($B36="","",SUMIFS('UPDATE STATS'!$J$5:$J$1004,'UPDATE STATS'!$B$5:$B$1004,$B36,'UPDATE STATS'!$T$5:$T$1004,mCrit)) -> 0 | K36: =IF($B36="","",IF(SUMIFS('UPDATE STATS'!$J$5:$J$1004,'UPDATE STATS'!$B$5:$B$1004,$B36,'UPDATE STATS'!$T$5:$T$1004,mCrit)>0,IFERROR(SUMIFS('UPDATE STATS'!$J$5:$J$1004,'UPDATE STATS'!$B$5:$B$1004,$B36,'UPDATE STATS'!$T$5:$T$1004,mCrit)/SUMIFS('UPDATE STATS'!$L$5:$L$1004,'UPDATE STATS'!$B$5:$B$1004,$B36,'UPDATE STATS'!$T$5:$T$1004,mCrit),""),"")) | L36: =IF($B36="","",COUNTIFS('PROGRAM STATUS'!$B$5:$B$654,$B36,'PROGRAM STATUS'!$E$5:$E$654,"Blocked")) -> 0
B37: =IF(CLIENTS!A15="","",CLIENTS!A15) -> Google Chrome Enterprise | D37: =IF($B37="","",IF(CLIENTS!B15="","",CLIENTS!B15)) -> Active | E37: =IF($B37="","",SUMIFS('UPDATE STATS'!$L$5:$L$1004,'UPDATE STATS'!$B$5:$B$1004,$B37,'UPDATE STATS'!$T$5:$T$1004,mCrit)) -> 0 | F37: =IF($B37="","",SUMIFS('UPDATE STATS'!$M$5:$M$1004,'UPDATE STATS'!$B$5:$B$1004,$B37,'UPDATE STATS'!$T$5:$T$1004,mCrit)) -> 0 | G37: =IF($B37="","",SUMIFS('UPDATE STATS'!$N$5:$N$1004,'UPDATE STATS'!$B$5:$B$1004,$B37,'UPDATE STATS'!$T$5:$T$1004,mCrit)) -> 0 | H37: =IF($B37="","",SUMIFS('UPDATE STATS'!$F$5:$F$1004,'UPDATE STATS'!$B$5:$B$1004,$B37,'UPDATE STATS'!$T$5:$T$1004,mCrit)) -> 0 | I37: =IF($B37="","",IFERROR(SUMIFS('UPDATE STATS'!$G$5:$G$1004,'UPDATE STATS'!$B$5:$B$1004,$B37,'UPDATE STATS'!$T$5:$T$1004,mCrit)/SUMIFS('UPDATE STATS'!$F$5:$F$1004,'UPDATE STATS'!$B$5:$B$1004,$B37,'UPDATE STATS'!$T$5:$T$1004,mCrit),"")) | J37: =IF($B37="","",SUMIFS('UPDATE STATS'!$J$5:$J$1004,'UPDATE STATS'!$B$5:$B$1004,$B37,'UPDATE STATS'!$T$5:$T$1004,mCrit)) -> 0 | K37: =IF($B37="","",IF(SUMIFS('UPDATE STATS'!$J$5:$J$1004,'UPDATE STATS'!$B$5:$B$1004,$B37,'UPDATE STATS'!$T$5:$T$1004,mCrit)>0,IFERROR(SUMIFS('UPDATE STATS'!$J$5:$J$1004,'UPDATE STATS'!$B$5:$B$1004,$B37,'UPDATE STATS'!$T$5:$T$1004,mCrit)/SUMIFS('UPDATE STATS'!$L$5:$L$1004,'UPDATE STATS'!$B$5:$B$1004,$B37,'UPDATE STATS'!$T$5:$T$1004,mCrit),""),"")) | L37: =IF($B37="","",COUNTIFS('PROGRAM STATUS'!$B$5:$B$654,$B37,'PROGRAM STATUS'!$E$5:$E$654,"Blocked")) -> 0
B38: =IF(CLIENTS!A16="","",CLIENTS!A16) -> Equinix | D38: =IF($B38="","",IF(CLIENTS!B16="","",CLIENTS!B16)) -> Active | E38: =IF($B38="","",SUMIFS('UPDATE STATS'!$L$5:$L$1004,'UPDATE STATS'!$B$5:$B$1004,$B38,'UPDATE STATS'!$T$5:$T$1004,mCrit)) -> 0 | F38: =IF($B38="","",SUMIFS('UPDATE STATS'!$M$5:$M$1004,'UPDATE STATS'!$B$5:$B$1004,$B38,'UPDATE STATS'!$T$5:$T$1004,mCrit)) -> 0 | G38: =IF($B38="","",SUMIFS('UPDATE STATS'!$N$5:$N$1004,'UPDATE STATS'!$B$5:$B$1004,$B38,'UPDATE STATS'!$T$5:$T$1004,mCrit)) -> 0 | H38: =IF($B38="","",SUMIFS('UPDATE STATS'!$F$5:$F$1004,'UPDATE STATS'!$B$5:$B$1004,$B38,'UPDATE STATS'!$T$5:$T$1004,mCrit)) -> 0 | I38: =IF($B38="","",IFERROR(SUMIFS('UPDATE STATS'!$G$5:$G$1004,'UPDATE STATS'!$B$5:$B$1004,$B38,'UPDATE STATS'!$T$5:$T$1004,mCrit)/SUMIFS('UPDATE STATS'!$F$5:$F$1004,'UPDATE STATS'!$B$5:$B$1004,$B38,'UPDATE STATS'!$T$5:$T$1004,mCrit),"")) | J38: =IF($B38="","",SUMIFS('UPDATE STATS'!$J$5:$J$1004,'UPDATE STATS'!$B$5:$B$1004,$B38,'UPDATE STATS'!$T$5:$T$1004,mCrit)) -> 0 | K38: =IF($B38="","",IF(SUMIFS('UPDATE STATS'!$J$5:$J$1004,'UPDATE STATS'!$B$5:$B$1004,$B38,'UPDATE STATS'!$T$5:$T$1004,mCrit)>0,IFERROR(SUMIFS('UPDATE STATS'!$J$5:$J$1004,'UPDATE STATS'!$B$5:$B$1004,$B38,'UPDATE STATS'!$T$5:$T$1004,mCrit)/SUMIFS('UPDATE STATS'!$L$5:$L$1004,'UPDATE STATS'!$B$5:$B$1004,$B38,'UPDATE STATS'!$T$5:$T$1004,mCrit),""),"")) | L38: =IF($B38="","",COUNTIFS('PROGRAM STATUS'!$B$5:$B$654,$B38,'PROGRAM STATUS'!$E$5:$E$654,"Blocked")) -> 0
... B51: =IF(CLIENTS!A29="","",CLIENTS!A29) | D51: =IF($B51="","",IF(CLIENTS!B29="","",CLIENTS!B29)) | E51: =IF($B51="","",SUMIFS('UPDATE STATS'!$L$5:$L$1004,'UPDATE STATS'!$B$5:$B$1004,$B51,'UPDATE STATS'!$T$5:$T$1004,mCrit)) | F51: =IF($B51="","",SUMIFS('UPDATE STATS'!$M$5:$M$1004,'UPDATE STATS'!$B$5:$B$1004,$B51,'UPDATE STATS'!$T$5:$T$1004,mCrit)) | G51: =IF($B51="","",SUMIFS('UPDATE STATS'!$N$5:$N$1004,'UPDATE STATS'!$B$5:$B$1004,$B51,'UPDATE STATS'!$T$5:$T$1004,mCrit)) | H51: =IF($B51="","",SUMIFS('UPDATE STATS'!$F$5:$F$1004,'UPDATE STATS'!$B$5:$B$1004,$B51,'UPDATE STATS'!$T$5:$T$1004,mCrit)) | I51: =IF($B51="","",IFERROR(SUMIFS('UPDATE STATS'!$G$5:$G$1004,'UPDATE STATS'!$B$5:$B$1004,$B51,'UPDATE STATS'!$T$5:$T$1004,mCrit)/SUMIFS('UPDATE STATS'!$F$5:$F$1004,'UPDATE STATS'!$B$5:$B$1004,$B51,'UPDATE STATS'!$T$5:$T$1004,mCrit),"")) | J51: =IF($B51="","",SUMIFS('UPDATE STATS'!$J$5:$J$1004,'UPDATE STATS'!$B$5:$B$1004,$B51,'UPDATE STATS'!$T$5:$T$1004,mCrit)) | K51: =IF($B51="","",IF(SUMIFS('UPDATE STATS'!$J$5:$J$1004,'UPDATE STATS'!$B$5:$B$1004,$B51,'UPDATE STATS'!$T$5:$T$1004,mCrit)>0,IFERROR(SUMIFS('UPDATE STATS'!$J$5:$J$1004,'UPDATE STATS'!$B$5:$B$1004,$B51,'UPDATE STATS'!$T$5:$T$1004,mCrit)/SUMIFS('UPDATE STATS'!$L$5:$L$1004,'UPDATE STATS'!$B$5:$B$1004,$B51,'UPDATE STATS'!$T$5:$T$1004,mCrit),""),"")) | L51: =IF($B51="","",COUNTIFS('PROGRAM STATUS'!$B$5:$B$654,$B51,'PROGRAM STATUS'!$E$5:$E$654,"Blocked"))
B53: LAST 6 MONTHS (Client filter applies)
B54: Month | D54: =YEAR(EDATE(DATE(YEAR(ReportDate),MONTH(ReportDate),1),-5))&"-"&TEXT(MONTH(EDATE(DATE(YEAR(ReportDate),MONTH(ReportDate),1),-5)),"00") -> 2026-05 | E54: =YEAR(EDATE(DATE(YEAR(ReportDate),MONTH(ReportDate),1),-4))&"-"&TEXT(MONTH(EDATE(DATE(YEAR(ReportDate),MONTH(ReportDate),1),-4)),"00") -> 2026-06 | F54: =YEAR(EDATE(DATE(YEAR(ReportDate),MONTH(ReportDate),1),-3))&"-"&TEXT(MONTH(EDATE(DATE(YEAR(ReportDate),MONTH(ReportDate),1),-3)),"00") -> 2026-07 | G54: =YEAR(EDATE(DATE(YEAR(ReportDate),MONTH(ReportDate),1),-2))&"-"&TEXT(MONTH(EDATE(DATE(YEAR(ReportDate),MONTH(ReportDate),1),-2)),"00") -> 2026-08 | H54: =YEAR(EDATE(DATE(YEAR(ReportDate),MONTH(ReportDate),1),-1))&"-"&TEXT(MONTH(EDATE(DATE(YEAR(ReportDate),MONTH(ReportDate),1),-1)),"00") -> 2026-09 | I54: =YEAR(EDATE(DATE(YEAR(ReportDate),MONTH(ReportDate),1),0))&"-"&TEXT(MONTH(EDATE(DATE(YEAR(ReportDate),MONTH(ReportDate),1),0)),"00") -> 2026-10
C55: Leads | D55: =SUMIFS('UPDATE STATS'!$L$5:$L$1004,'UPDATE STATS'!$T$5:$T$1004,D$54,'UPDATE STATS'!$B$5:$B$1004,cCrit) -> 0 | E55: =SUMIFS('UPDATE STATS'!$L$5:$L$1004,'UPDATE STATS'!$T$5:$T$1004,E$54,'UPDATE STATS'!$B$5:$B$1004,cCrit) -> 0 | F55: =SUMIFS('UPDATE STATS'!$L$5:$L$1004,'UPDATE STATS'!$T$5:$T$1004,F$54,'UPDATE STATS'!$B$5:$B$1004,cCrit) -> 0 | G55: =SUMIFS('UPDATE STATS'!$L$5:$L$1004,'UPDATE STATS'!$T$5:$T$1004,G$54,'UPDATE STATS'!$B$5:$B$1004,cCrit) -> 0 | H55: =SUMIFS('UPDATE STATS'!$L$5:$L$1004,'UPDATE STATS'!$T$5:$T$1004,H$54,'UPDATE STATS'!$B$5:$B$1004,cCrit) -> 0 | I55: =SUMIFS('UPDATE STATS'!$L$5:$L$1004,'UPDATE STATS'!$T$5:$T$1004,I$54,'UPDATE STATS'!$B$5:$B$1004,cCrit) -> 0
C56: MQLs | D56: =SUMIFS('UPDATE STATS'!$M$5:$M$1004,'UPDATE STATS'!$T$5:$T$1004,D$54,'UPDATE STATS'!$B$5:$B$1004,cCrit) -> 0 | E56: =SUMIFS('UPDATE STATS'!$M$5:$M$1004,'UPDATE STATS'!$T$5:$T$1004,E$54,'UPDATE STATS'!$B$5:$B$1004,cCrit) -> 0 | F56: =SUMIFS('UPDATE STATS'!$M$5:$M$1004,'UPDATE STATS'!$T$5:$T$1004,F$54,'UPDATE STATS'!$B$5:$B$1004,cCrit) -> 0 | G56: =SUMIFS('UPDATE STATS'!$M$5:$M$1004,'UPDATE STATS'!$T$5:$T$1004,G$54,'UPDATE STATS'!$B$5:$B$1004,cCrit) -> 0 | H56: =SUMIFS('UPDATE STATS'!$M$5:$M$1004,'UPDATE STATS'!$T$5:$T$1004,H$54,'UPDATE STATS'!$B$5:$B$1004,cCrit) -> 0 | I56: =SUMIFS('UPDATE STATS'!$M$5:$M$1004,'UPDATE STATS'!$T$5:$T$1004,I$54,'UPDATE STATS'!$B$5:$B$1004,cCrit) -> 0
C57: SQLs | D57: =SUMIFS('UPDATE STATS'!$N$5:$N$1004,'UPDATE STATS'!$T$5:$T$1004,D$54,'UPDATE STATS'!$B$5:$B$1004,cCrit) -> 0 | E57: =SUMIFS('UPDATE STATS'!$N$5:$N$1004,'UPDATE STATS'!$T$5:$T$1004,E$54,'UPDATE STATS'!$B$5:$B$1004,cCrit) -> 0 | F57: =SUMIFS('UPDATE STATS'!$N$5:$N$1004,'UPDATE STATS'!$T$5:$T$1004,F$54,'UPDATE STATS'!$B$5:$B$1004,cCrit) -> 0 | G57: =SUMIFS('UPDATE STATS'!$N$5:$N$1004,'UPDATE STATS'!$T$5:$T$1004,G$54,'UPDATE STATS'!$B$5:$B$1004,cCrit) -> 0 | H57: =SUMIFS('UPDATE STATS'!$N$5:$N$1004,'UPDATE STATS'!$T$5:$T$1004,H$54,'UPDATE STATS'!$B$5:$B$1004,cCrit) -> 0 | I57: =SUMIFS('UPDATE STATS'!$N$5:$N$1004,'UPDATE STATS'!$T$5:$T$1004,I$54,'UPDATE STATS'!$B$5:$B$1004,cCrit) -> 0
C58: Emails Sent | D58: =SUMIFS('UPDATE STATS'!$F$5:$F$1004,'UPDATE STATS'!$T$5:$T$1004,D$54,'UPDATE STATS'!$B$5:$B$1004,cCrit) -> 0 | E58: =SUMIFS('UPDATE STATS'!$F$5:$F$1004,'UPDATE STATS'!$T$5:$T$1004,E$54,'UPDATE STATS'!$B$5:$B$1004,cCrit) -> 0 | F58: =SUMIFS('UPDATE STATS'!$F$5:$F$1004,'UPDATE STATS'!$T$5:$T$1004,F$54,'UPDATE STATS'!$B$5:$B$1004,cCrit) -> 0 | G58: =SUMIFS('UPDATE STATS'!$F$5:$F$1004,'UPDATE STATS'!$T$5:$T$1004,G$54,'UPDATE STATS'!$B$5:$B$1004,cCrit) -> 0 | H58: =SUMIFS('UPDATE STATS'!$F$5:$F$1004,'UPDATE STATS'!$T$5:$T$1004,H$54,'UPDATE STATS'!$B$5:$B$1004,cCrit) -> 0 | I58: =SUMIFS('UPDATE STATS'!$F$5:$F$1004,'UPDATE STATS'!$T$5:$T$1004,I$54,'UPDATE STATS'!$B$5:$B$1004,cCrit) -> 0
C59: Ad Spend | D59: =SUMIFS('UPDATE STATS'!$J$5:$J$1004,'UPDATE STATS'!$T$5:$T$1004,D$54,'UPDATE STATS'!$B$5:$B$1004,cCrit) -> 0 | E59: =SUMIFS('UPDATE STATS'!$J$5:$J$1004,'UPDATE STATS'!$T$5:$T$1004,E$54,'UPDATE STATS'!$B$5:$B$1004,cCrit) -> 0 | F59: =SUMIFS('UPDATE STATS'!$J$5:$J$1004,'UPDATE STATS'!$T$5:$T$1004,F$54,'UPDATE STATS'!$B$5:$B$1004,cCrit) -> 0 | G59: =SUMIFS('UPDATE STATS'!$J$5:$J$1004,'UPDATE STATS'!$T$5:$T$1004,G$54,'UPDATE STATS'!$B$5:$B$1004,cCrit) -> 0 | H59: =SUMIFS('UPDATE STATS'!$J$5:$J$1004,'UPDATE STATS'!$T$5:$T$1004,H$54,'UPDATE STATS'!$B$5:$B$1004,cCrit) -> 0 | I59: =SUMIFS('UPDATE STATS'!$J$5:$J$1004,'UPDATE STATS'!$T$5:$T$1004,I$54,'UPDATE STATS'!$B$5:$B$1004,cCrit) -> 0
...

Sheet UPDATE STATS
A1: UPDATE STATS - enter your numbers here
A2: BLUE cells = team enters data | GREY cells = automatic formulas (do not edit) | One row per update (daily or weekly). Fill only what applies. Enter numbers for THAT period, not running totals.
A3: Example: 05-Oct-26 | SAP | SAP Viksit Bharat | Email | Surbhi Pandey | 5000 | 900 | 120 | 20 | 0 | 2 | 25 | 6 | 1 ...
A4: Date | B4: Client | C4: Campaign | D4: Channel | E4: Your Name | F4: Emails Sent | G4: Opens | H4: Clicks | I4: Replies | J4: Ad Spend | K4: Handraisers | L4: Leads | M4: MQLs | N4: SQLs | O4: Opportunities | P4: Notes | Q4: Open Rate | R4: Click Rate | S4: Cost per Lead | T4: Month
Q5: =IF(AND(ISNUMBER($F5),$F5>0,ISNUMBER($G5)),$G5/$F5,"") | R5: =IF(AND(ISNUMBER($F5),$F5>0,ISNUMBER($H5)),$H5/$F5,"") | S5: =IF(AND(ISNUMBER($J5),ISNUMBER($L5)),IF($L5>0,$J5/$L5,""),"") | T5: =IF(ISNUMBER($A5),YEAR($A5)&"-"&TEXT(MONTH($A5),"00"),"")
Q6: =IF(AND(ISNUMBER($F6),$F6>0,ISNUMBER($G6)),$G6/$F6,"") | R6: =IF(AND(ISNUMBER($F6),$F6>0,ISNUMBER($H6)),$H6/$F6,"") | S6: =IF(AND(ISNUMBER($J6),ISNUMBER($L6)),IF($L6>0,$J6/$L6,""),"") | T6: =IF(ISNUMBER($A6),YEAR($A6)&"-"&TEXT(MONTH($A6),"00"),"")
Q7: =IF(AND(ISNUMBER($F7),$F7>0,ISNUMBER($G7)),$G7/$F7,"") | R7: =IF(AND(ISNUMBER($F7),$F7>0,ISNUMBER($H7)),$H7/$F7,"") | S7: =IF(AND(ISNUMBER($J7),ISNUMBER($L7)),IF($L7>0,$J7/$L7,""),"") | T7: =IF(ISNUMBER($A7),YEAR($A7)&"-"&TEXT(MONTH($A7),"00"),"")
Q8: =IF(AND(ISNUMBER($F8),$F8>0,ISNUMBER($G8)),$G8/$F8,"") | R8: =IF(AND(ISNUMBER($F8),$F8>0,ISNUMBER($H8)),$H8/$F8,"") | S8: =IF(AND(ISNUMBER($J8),ISNUMBER($L8)),IF($L8>0,$J8/$L8,""),"") | T8: =IF(ISNUMBER($A8),YEAR($A8)&"-"&TEXT(MONTH($A8),"00"),"")
Q9: =IF(AND(ISNUMBER($F9),$F9>0,ISNUMBER($G9)),$G9/$F9,"") | R9: =IF(AND(ISNUMBER($F9),$F9>0,ISNUMBER($H9)),$H9/$F9,"") | S9: =IF(AND(ISNUMBER($J9),ISNUMBER($L9)),IF($L9>0,$J9/$L9,""),"") | T9: =IF(ISNUMBER($A9),YEAR($A9)&"-"&TEXT(MONTH($A9),"00"),"")
Q10: =IF(AND(ISNUMBER($F10),$F10>0,ISNUMBER($G10)),$G10/$F10,"") | R10: =IF(AND(ISNUMBER($F10),$F10>0,ISNUMBER($H10)),$H10/$F10,"") | S10: =IF(AND(ISNUMBER($J10),ISNUMBER($L10)),IF($L10>0,$J10/$L10,""),"") | T10: =IF(ISNUMBER($A10),YEAR($A10)&"-"&TEXT(MONTH($A10),"00"),"")
Q11: =IF(AND(ISNUMBER($F11),$F11>0,ISNUMBER($G11)),$G11/$F11,"") | R11: =IF(AND(ISNUMBER($F11),$F11>0,ISNUMBER($H11)),$H11/$F11,"") | S11: =IF(AND(ISNUMBER($J11),ISNUMBER($L11)),IF($L11>0,$J11/$L11,""),"") | T11: =IF(ISNUMBER($A11),YEAR($A11)&"-"&TEXT(MONTH($A11),"00"),"")
Q12: =IF(AND(ISNUMBER($F12),$F12>0,ISNUMBER($G12)),$G12/$F12,"") | R12: =IF(AND(ISNUMBER($F12),$F12>0,ISNUMBER($H12)),$H12/$F12,"") | S12: =IF(AND(ISNUMBER($J12),ISNUMBER($L12)),IF($L12>0,$J12/$L12,""),"") | T12: =IF(ISNUMBER($A12),YEAR($A12)&"-"&TEXT(MONTH($A12),"00"),"")
Q13: =IF(AND(ISNUMBER($F13),$F13>0,ISNUMBER($G13)),$G13/$F13,"") | R13: =IF(AND(ISNUMBER($F13),$F13>0,ISNUMBER($H13)),$H13/$F13,"") | S13: =IF(AND(ISNUMBER($J13),ISNUMBER($L13)),IF($L13>0,$J13/$L13,""),"") | T13: =IF(ISNUMBER($A13),YEAR($A13)&"-"&TEXT(MONTH($A13),"00"),"")
Q14: =IF(AND(ISNUMBER($F14),$F14>0,ISNUMBER($G14)),$G14/$F14,"") | R14: =IF(AND(ISNUMBER($F14),$F14>0,ISNUMBER($H14)),$H14/$F14,"") | S14: =IF(AND(ISNUMBER($J14),ISNUMBER($L14)),IF($L14>0,$J14/$L14,""),"") | T14: =IF(ISNUMBER($A14),YEAR($A14)&"-"&TEXT(MONTH($A14),"00"),"")
Q15: =IF(AND(ISNUMBER($F15),$F15>0,ISNUMBER($G15)),$G15/$F15,"") | R15: =IF(AND(ISNUMBER($F15),$F15>0,ISNUMBER($H15)),$H15/$F15,"") | S15: =IF(AND(ISNUMBER($J15),ISNUMBER($L15)),IF($L15>0,$J15/$L15,""),"") | T15: =IF(ISNUMBER($A15),YEAR($A15)&"-"&TEXT(MONTH($A15),"00"),"")
Q16: =IF(AND(ISNUMBER($F16),$F16>0,ISNUMBER($G16)),$G16/$F16,"") | R16: =IF(AND(ISNUMBER($F16),$F16>0,ISNUMBER($H16)),$H16/$F16,"") | S16: =IF(AND(ISNUMBER($J16),ISNUMBER($L16)),IF($L16>0,$J16/$L16,""),"") | T16: =IF(ISNUMBER($A16),YEAR($A16)&"-"&TEXT(MONTH($A16),"00"),"")
... Q504: =IF(AND(ISNUMBER($F504),$F504>0,ISNUMBER($G504)),$G504/$F504,"") | R504: =IF(AND(ISNUMBER($F504),$F504>0,ISNUMBER($H504)),$H504/$F504,"") | S504: =IF(AND(ISNUMBER($J504),ISNUMBER($L504)),IF($L504>0,$J504/$L504,""),"") | T504: =IF(ISNUMBER($A504),YEAR($A504)&"-"&TEXT(MONTH($A504),"00"),"")

Sheet CAMPAIGNS
A1: CAMPAIGNS - one row per campaign
A2: BLUE cells = team enters data | GREY cells = automatic formulas (do not edit) | Fill the blue columns. Leads, MQLs and spend fill in automatically from UPDATE STATS.
A4: Client | B4: Campaign Name | C4: Channel | D4: Owner | E4: Status | F4: Start Date | G4: End Date | H4: Leads Target | I4: Remarks | J4: Leads So Far | K4: MQLs So Far | L4: Spend So Far | M4: % of Target | N4: Last Stats Entry | O4: Check
A5: SAP | B5: SAP Partner Campaign - Citek | C5: Content Syndication | D5: Surbhi Pandey | I5: Content Syndication - Email. Status/dates not provided in baseline. | J5: =IF($B5="","",SUMIFS('UPDATE STATS'!$L$5:$L$1004,'UPDATE STATS'!$C$5:$C$1004,$B5)) -> 0 | K5: =IF($B5="","",SUMIFS('UPDATE STATS'!$M$5:$M$1004,'UPDATE STATS'!$C$5:$C$1004,$B5)) -> 0 | L5: =IF($B5="","",SUMIFS('UPDATE STATS'!$J$5:$J$1004,'UPDATE STATS'!$C$5:$C$1004,$B5)) -> 0 | M5: =IF(AND(ISNUMBER($H5),$H5>0,ISNUMBER($J5)),$J5/$H5,"") | N5: =IF($B5="","",IF(COUNTIFS('UPDATE STATS'!$C$5:$C$1004,$B5,'UPDATE STATS'!$A$5:$A$1004,">0")=0,"",_xlfn.MAXIFS('UPDATE STATS'!$A$5:$A$1004,'UPDATE STATS'!$C$5:$C$1004,$B5))) | O5: =IF($B5="","",IF($E5<>"Live","",IF($N5="","No stats yet",IF(ReportDate-$N5>7,"Update needed",IF(AND(ISNUMBER($M5),$M5<0.5),"Behind target","OK")))))
A6: SAP | B6: SAP Partner Campaign - Apptech | C6: Content Syndication | D6: Surbhi Pandey | I6: Content Syndication - Email. Status/dates not provided in baseline. | J6: =IF($B6="","",SUMIFS('UPDATE STATS'!$L$5:$L$1004,'UPDATE STATS'!$C$5:$C$1004,$B6)) -> 0 | K6: =IF($B6="","",SUMIFS('UPDATE STATS'!$M$5:$M$1004,'UPDATE STATS'!$C$5:$C$1004,$B6)) -> 0 | L6: =IF($B6="","",SUMIFS('UPDATE STATS'!$J$5:$J$1004,'UPDATE STATS'!$C$5:$C$1004,$B6)) -> 0 | M6: =IF(AND(ISNUMBER($H6),$H6>0,ISNUMBER($J6)),$J6/$H6,"") | N6: =IF($B6="","",IF(COUNTIFS('UPDATE STATS'!$C$5:$C$1004,$B6,'UPDATE STATS'!$A$5:$A$1004,">0")=0,"",_xlfn.MAXIFS('UPDATE STATS'!$A$5:$A$1004,'UPDATE STATS'!$C$5:$C$1004,$B6))) | O6: =IF($B6="","",IF($E6<>"Live","",IF($N6="","No stats yet",IF(ReportDate-$N6>7,"Update needed",IF(AND(ISNUMBER($M6),$M6<0.5),"Behind target","OK")))))
A7: SAP | B7: SAP Partner Campaign - Netizen | C7: Content Syndication | D7: Surbhi Pandey | I7: Content Syndication - Email. Status/dates not provided in baseline. | J7: =IF($B7="","",SUMIFS('UPDATE STATS'!$L$5:$L$1004,'UPDATE STATS'!$C$5:$C$1004,$B7)) -> 0 | K7: =IF($B7="","",SUMIFS('UPDATE STATS'!$M$5:$M$1004,'UPDATE STATS'!$C$5:$C$1004,$B7)) -> 0 | L7: =IF($B7="","",SUMIFS('UPDATE STATS'!$J$5:$J$1004,'UPDATE STATS'!$C$5:$C$1004,$B7)) -> 0 | M7: =IF(AND(ISNUMBER($H7),$H7>0,ISNUMBER($J7)),$J7/$H7,"") | N7: =IF($B7="","",IF(COUNTIFS('UPDATE STATS'!$C$5:$C$1004,$B7,'UPDATE STATS'!$A$5:$A$1004,">0")=0,"",_xlfn.MAXIFS('UPDATE STATS'!$A$5:$A$1004,'UPDATE STATS'!$C$5:$C$1004,$B7))) | O7: =IF($B7="","",IF($E7<>"Live","",IF($N7="","No stats yet",IF(ReportDate-$N7>7,"Update needed",IF(AND(ISNUMBER($M7),$M7<0.5),"Behind target","OK")))))
A8: SAP | B8: SAP Partner Campaign - Ikyam | C8: Content Syndication | D8: Surbhi Pandey | I8: Content Syndication - Email. Status/dates not provided in baseline. | J8: =IF($B8="","",SUMIFS('UPDATE STATS'!$L$5:$L$1004,'UPDATE STATS'!$C$5:$C$1004,$B8)) -> 0 | K8: =IF($B8="","",SUMIFS('UPDATE STATS'!$M$5:$M$1004,'UPDATE STATS'!$C$5:$C$1004,$B8)) -> 0 | L8: =IF($B8="","",SUMIFS('UPDATE STATS'!$J$5:$J$1004,'UPDATE STATS'!$C$5:$C$1004,$B8)) -> 0 | M8: =IF(AND(ISNUMBER($H8),$H8>0,ISNUMBER($J8)),$J8/$H8,"") | N8: =IF($B8="","",IF(COUNTIFS('UPDATE STATS'!$C$5:$C$1004,$B8,'UPDATE STATS'!$A$5:$A$1004,">0")=0,"",_xlfn.MAXIFS('UPDATE STATS'!$A$5:$A$1004,'UPDATE STATS'!$C$5:$C$1004,$B8))) | O8: =IF($B8="","",IF($E8<>"Live","",IF($N8="","No stats yet",IF(ReportDate-$N8>7,"Update needed",IF(AND(ISNUMBER($M8),$M8<0.5),"Behind target","OK")))))
A9: SAP | B9: SAP Partner Campaign - Castaliaz | C9: Content Syndication | D9: Surbhi Pandey | I9: Content Syndication - Email. Status/dates not provided in baseline. | J9: =IF($B9="","",SUMIFS('UPDATE STATS'!$L$5:$L$1004,'UPDATE STATS'!$C$5:$C$1004,$B9)) -> 0 | K9: =IF($B9="","",SUMIFS('UPDATE STATS'!$M$5:$M$1004,'UPDATE STATS'!$C$5:$C$1004,$B9)) -> 0 | L9: =IF($B9="","",SUMIFS('UPDATE STATS'!$J$5:$J$1004,'UPDATE STATS'!$C$5:$C$1004,$B9)) -> 0 | M9: =IF(AND(ISNUMBER($H9),$H9>0,ISNUMBER($J9)),$J9/$H9,"") | N9: =IF($B9="","",IF(COUNTIFS('UPDATE STATS'!$C$5:$C$1004,$B9,'UPDATE STATS'!$A$5:$A$1004,">0")=0,"",_xlfn.MAXIFS('UPDATE STATS'!$A$5:$A$1004,'UPDATE STATS'!$C$5:$C$1004,$B9))) | O9: =IF($B9="","",IF($E9<>"Live","",IF($N9="","No stats yet",IF(ReportDate-$N9>7,"Update needed",IF(AND(ISNUMBER($M9),$M9<0.5),"Behind target","OK")))))
A10: SAP | B10: SAP Partner Campaign - Truspeq | C10: Content Syndication | D10: Surbhi Pandey | I10: Content Syndication - Email. Status/dates not provided in baseline. | J10: =IF($B10="","",SUMIFS('UPDATE STATS'!$L$5:$L$1004,'UPDATE STATS'!$C$5:$C$1004,$B10)) -> 0 | K10: =IF($B10="","",SUMIFS('UPDATE STATS'!$M$5:$M$1004,'UPDATE STATS'!$C$5:$C$1004,$B10)) -> 0 | L10: =IF($B10="","",SUMIFS('UPDATE STATS'!$J$5:$J$1004,'UPDATE STATS'!$C$5:$C$1004,$B10)) -> 0 | M10: =IF(AND(ISNUMBER($H10),$H10>0,ISNUMBER($J10)),$J10/$H10,"") | N10: =IF($B10="","",IF(COUNTIFS('UPDATE STATS'!$C$5:$C$1004,$B10,'UPDATE STATS'!$A$5:$A$1004,">0")=0,"",_xlfn.MAXIFS('UPDATE STATS'!$A$5:$A$1004,'UPDATE STATS'!$C$5:$C$1004,$B10))) | O10: =IF($B10="","",IF($E10<>"Live","",IF($N10="","No stats yet",IF(ReportDate-$N10>7,"Update needed",IF(AND(ISNUMBER($M10),$M10<0.5),"Behind target","OK")))))
A11: SAP | B11: SAP Partner Campaign - NTT Data | C11: Content Syndication | D11: Surbhi Pandey | I11: Content Syndication - Email. Status/dates not provided in baseline. | J11: =IF($B11="","",SUMIFS('UPDATE STATS'!$L$5:$L$1004,'UPDATE STATS'!$C$5:$C$1004,$B11)) -> 0 | K11: =IF($B11="","",SUMIFS('UPDATE STATS'!$M$5:$M$1004,'UPDATE STATS'!$C$5:$C$1004,$B11)) -> 0 | L11: =IF($B11="","",SUMIFS('UPDATE STATS'!$J$5:$J$1004,'UPDATE STATS'!$C$5:$C$1004,$B11)) -> 0 | M11: =IF(AND(ISNUMBER($H11),$H11>0,ISNUMBER($J11)),$J11/$H11,"") | N11: =IF($B11="","",IF(COUNTIFS('UPDATE STATS'!$C$5:$C$1004,$B11,'UPDATE STATS'!$A$5:$A$1004,">0")=0,"",_xlfn.MAXIFS('UPDATE STATS'!$A$5:$A$1004,'UPDATE STATS'!$C$5:$C$1004,$B11))) | O11: =IF($B11="","",IF($E11<>"Live","",IF($N11="","No stats yet",IF(ReportDate-$N11>7,"Update needed",IF(AND(ISNUMBER($M11),$M11<0.5),"Behind target","OK")))))
A12: SAP | B12: SAP Partner Campaign - Abeam TH | C12: Content Syndication | D12: Surbhi Pandey | I12: Content Syndication - Email. Status/dates not provided in baseline. | J12: =IF($B12="","",SUMIFS('UPDATE STATS'!$L$5:$L$1004,'UPDATE STATS'!$C$5:$C$1004,$B12)) -> 0 | K12: =IF($B12="","",SUMIFS('UPDATE STATS'!$M$5:$M$1004,'UPDATE STATS'!$C$5:$C$1004,$B12)) -> 0 | L12: =IF($B12="","",SUMIFS('UPDATE STATS'!$J$5:$J$1004,'UPDATE STATS'!$C$5:$C$1004,$B12)) -> 0 | M12: =IF(AND(ISNUMBER($H12),$H12>0,ISNUMBER($J12)),$J12/$H12,"") | N12: =IF($B12="","",IF(COUNTIFS('UPDATE STATS'!$C$5:$C$1004,$B12,'UPDATE STATS'!$A$5:$A$1004,">0")=0,"",_xlfn.MAXIFS('UPDATE STATS'!$A$5:$A$1004,'UPDATE STATS'!$C$5:$C$1004,$B12))) | O12: =IF($B12="","",IF($E12<>"Live","",IF($N12="","No stats yet",IF(ReportDate-$N12>7,"Update needed",IF(AND(ISNUMBER($M12),$M12<0.5),"Behind target","OK")))))
A13: Utimaco Singapore | B13: Utimaco Singapore | C13: Content Syndication | D13: Surbhi Pandey | I13: Content Syndication - Email. | J13: =IF($B13="","",SUMIFS('UPDATE STATS'!$L$5:$L$1004,'UPDATE STATS'!$C$5:$C$1004,$B13)) -> 0 | K13: =IF($B13="","",SUMIFS('UPDATE STATS'!$M$5:$M$1004,'UPDATE STATS'!$C$5:$C$1004,$B13)) -> 0 | L13: =IF($B13="","",SUMIFS('UPDATE STATS'!$J$5:$J$1004,'UPDATE STATS'!$C$5:$C$1004,$B13)) -> 0 | M13: =IF(AND(ISNUMBER($H13),$H13>0,ISNUMBER($J13)),$J13/$H13,"") | N13: =IF($B13="","",IF(COUNTIFS('UPDATE STATS'!$C$5:$C$1004,$B13,'UPDATE STATS'!$A$5:$A$1004,">0")=0,"",_xlfn.MAXIFS('UPDATE STATS'!$A$5:$A$1004,'UPDATE STATS'!$C$5:$C$1004,$B13))) | O13: =IF($B13="","",IF($E13<>"Live","",IF($N13="","No stats yet",IF(ReportDate-$N13>7,"Update needed",IF(AND(ISNUMBER($M13),$M13<0.5),"Behind target","OK")))))
A14: SAP | B14: SAP Success Factor HR Bengaluru | C14: Content Syndication | D14: Surbhi Pandey | I14: Email + WhatsApp. Deployments: 25th Sep and 9th Oct (year assumed 2026). | J14: =IF($B14="","",SUMIFS('UPDATE STATS'!$L$5:$L$1004,'UPDATE STATS'!$C$5:$C$1004,$B14)) -> 0 | K14: =IF($B14="","",SUMIFS('UPDATE STATS'!$M$5:$M$1004,'UPDATE STATS'!$C$5:$C$1004,$B14)) -> 0 | L14: =IF($B14="","",SUMIFS('UPDATE STATS'!$J$5:$J$1004,'UPDATE STATS'!$C$5:$C$1004,$B14)) -> 0 | M14: =IF(AND(ISNUMBER($H14),$H14>0,ISNUMBER($J14)),$J14/$H14,"") | N14: =IF($B14="","",IF(COUNTIFS('UPDATE STATS'!$C$5:$C$1004,$B14,'UPDATE STATS'!$A$5:$A$1004,">0")=0,"",_xlfn.MAXIFS('UPDATE STATS'!$A$5:$A$1004,'UPDATE STATS'!$C$5:$C$1004,$B14))) | O14: =IF($B14="","",IF($E14<>"Live","",IF($N14="","No stats yet",IF(ReportDate-$N14>7,"Update needed",IF(AND(ISNUMBER($M14),$M14<0.5),"Behind target","OK")))))
A15: SAP | B15: SAP Viksit Bharat | C15: Content Syndication | D15: Surbhi Pandey | I15: Email + WhatsApp. Deployments: 25th Sep and 6th Oct (year assumed 2026). | J15: =IF($B15="","",SUMIFS('UPDATE STATS'!$L$5:$L$1004,'UPDATE STATS'!$C$5:$C$1004,$B15)) -> 0 | K15: =IF($B15="","",SUMIFS('UPDATE STATS'!$M$5:$M$1004,'UPDATE STATS'!$C$5:$C$1004,$B15)) -> 0 | L15: =IF($B15="","",SUMIFS('UPDATE STATS'!$J$5:$J$1004,'UPDATE STATS'!$C$5:$C$1004,$B15)) -> 0 | M15: =IF(AND(ISNUMBER($H15),$H15>0,ISNUMBER($J15)),$J15/$H15,"") | N15: =IF($B15="","",IF(COUNTIFS('UPDATE STATS'!$C$5:$C$1004,$B15,'UPDATE STATS'!$A$5:$A$1004,">0")=0,"",_xlfn.MAXIFS('UPDATE STATS'!$A$5:$A$1004,'UPDATE STATS'!$C$5:$C$1004,$B15))) | O15: =IF($B15="","",IF($E15<>"Live","",IF($N15="","No stats yet",IF(ReportDate-$N15>7,"Update needed",IF(AND(ISNUMBER($M15),$M15<0.5),"Behind target","OK")))))
A16: SAP | B16: SAP Success Factor Delhi | C16: Content Syndication | D16: Surbhi Pandey | I16: Email + WhatsApp. Deployment: 30th Sep (year assumed 2026). | J16: =IF($B16="","",SUMIFS('UPDATE STATS'!$L$5:$L$1004,'UPDATE STATS'!$C$5:$C$1004,$B16)) -> 0 | K16: =IF($B16="","",SUMIFS('UPDATE STATS'!$M$5:$M$1004,'UPDATE STATS'!$C$5:$C$1004,$B16)) -> 0 | L16: =IF($B16="","",SUMIFS('UPDATE STATS'!$J$5:$J$1004,'UPDATE STATS'!$C$5:$C$1004,$B16)) -> 0 | M16: =IF(AND(ISNUMBER($H16),$H16>0,ISNUMBER($J16)),$J16/$H16,"") | N16: =IF($B16="","",IF(COUNTIFS('UPDATE STATS'!$C$5:$C$1004,$B16,'UPDATE STATS'!$A$5:$A$1004,">0")=0,"",_xlfn.MAXIFS('UPDATE STATS'!$A$5:$A$1004,'UPDATE STATS'!$C$5:$C$1004,$B16))) | O16: =IF($B16="","",IF($E16<>"Live","",IF($N16="","No stats yet",IF(ReportDate-$N16>7,"Update needed",IF(AND(ISNUMBER($M16),$M16<0.5),"Behind target","OK")))))
... A20: Magnasoft | B20: Magnasoft - Google Ads | C20: Google Ads | D20: Richi Bagla | I20: Target: 'No update' in Project Updates. | J20: =IF($B20="","",SUMIFS('UPDATE STATS'!$L$5:$L$1004,'UPDATE STATS'!$C$5:$C$1004,$B20)) -> 0 | K20: =IF($B20="","",SUMIFS('UPDATE STATS'!$M$5:$M$1004,'UPDATE STATS'!$C$5:$C$1004,$B20)) -> 0 | L20: =IF($B20="","",SUMIFS('UPDATE STATS'!$J$5:$J$1004,'UPDATE STATS'!$C$5:$C$1004,$B20)) -> 0 | M20: =IF(AND(ISNUMBER($H20),$H20>0,ISNUMBER($J20)),$J20/$H20,"") | N20: =IF($B20="","",IF(COUNTIFS('UPDATE STATS'!$C$5:$C$1004,$B20,'UPDATE STATS'!$A$5:$A$1004,">0")=0,"",_xlfn.MAXIFS('UPDATE STATS'!$A$5:$A$1004,'UPDATE STATS'!$C$5:$C$1004,$B20))) | O20: =IF($B20="","",IF($E20<>"Live","",IF($N20="","No stats yet",IF(ReportDate-$N20>7,"Update needed",IF(AND(ISNUMBER($M20),$M20<0.5),"Behind target","OK")))))
A21: Ruckus Networks | B21: Ruckus - Content Syndication (Email) | C21: Content Syndication | D21: Richi Bagla | H21: 50 | I21: Target: 50 form fills (Project Updates); 50 leads over 3 months (billing sheet). | J21: =IF($B21="","",SUMIFS('UPDATE STATS'!$L$5:$L$1004,'UPDATE STATS'!$C$5:$C$1004,$B21)) -> 0 | K21: =IF($B21="","",SUMIFS('UPDATE STATS'!$M$5:$M$1004,'UPDATE STATS'!$C$5:$C$1004,$B21)) -> 0 | L21: =IF($B21="","",SUMIFS('UPDATE STATS'!$J$5:$J$1004,'UPDATE STATS'!$C$5:$C$1004,$B21)) -> 0 | M21: =IF(AND(ISNUMBER($H21),$H21>0,ISNUMBER($J21)),$J21/$H21,"") -> 0 | N21: =IF($B21="","",IF(COUNTIFS('UPDATE STATS'!$C$5:$C$1004,$B21,'UPDATE STATS'!$A$5:$A$1004,">0")=0,"",_xlfn.MAXIFS('UPDATE STATS'!$A$5:$A$1004,'UPDATE STATS'!$C$5:$C$1004,$B21))) | O21: =IF($B21="","",IF($E21<>"Live","",IF($N21="","No stats yet",IF(ReportDate-$N21>7,"Update needed",IF(AND(ISNUMBER($M21),$M21<0.5),"Behind target","OK")))))
A22: Equinix | B22: Equinix - Content Syndication (Email) | C22: Content Syndication | D22: Richi Bagla | H22: 150 | I22: Target: 150 form fills (Project Updates); 150 leads by Dec'26 (billing sheet). | J22: =IF($B22="","",SUMIFS('UPDATE STATS'!$L$5:$L$1004,'UPDATE STATS'!$C$5:$C$1004,$B22)) -> 0 | K22: =IF($B22="","",SUMIFS('UPDATE STATS'!$M$5:$M$1004,'UPDATE STATS'!$C$5:$C$1004,$B22)) -> 0 | L22: =IF($B22="","",SUMIFS('UPDATE STATS'!$J$5:$J$1004,'UPDATE STATS'!$C$5:$C$1004,$B22)) -> 0 | M22: =IF(AND(ISNUMBER($H22),$H22>0,ISNUMBER($J22)),$J22/$H22,"") -> 0 | N22: =IF($B22="","",IF(COUNTIFS('UPDATE STATS'!$C$5:$C$1004,$B22,'UPDATE STATS'!$A$5:$A$1004,">0")=0,"",_xlfn.MAXIFS('UPDATE STATS'!$A$5:$A$1004,'UPDATE STATS'!$C$5:$C$1004,$B22))) | O22: =IF($B22="","",IF($E22<>"Live","",IF($N22="","No stats yet",IF(ReportDate-$N22>7,"Update needed",IF(AND(ISNUMBER($M22),$M22<0.5),"Behind target","OK")))))
A23: Google Chrome Enterprise | B23: Google Chrome - Content Syndication (Email) | C23: Content Syndication | D23: Riya Diwan | I23: Reporting needs: form fills, opens/clicks data. | J23: =IF($B23="","",SUMIFS('UPDATE STATS'!$L$5:$L$1004,'UPDATE STATS'!$C$5:$C$1004,$B23)) -> 0 | K23: =IF($B23="","",SUMIFS('UPDATE STATS'!$M$5:$M$1004,'UPDATE STATS'!$C$5:$C$1004,$B23)) -> 0 | L23: =IF($B23="","",SUMIFS('UPDATE STATS'!$J$5:$J$1004,'UPDATE STATS'!$C$5:$C$1004,$B23)) -> 0 | M23: =IF(AND(ISNUMBER($H23),$H23>0,ISNUMBER($J23)),$J23/$H23,"") | N23: =IF($B23="","",IF(COUNTIFS('UPDATE STATS'!$C$5:$C$1004,$B23,'UPDATE STATS'!$A$5:$A$1004,">0")=0,"",_xlfn.MAXIFS('UPDATE STATS'!$A$5:$A$1004,'UPDATE STATS'!$C$5:$C$1004,$B23))) | O23: =IF($B23="","",IF($E23<>"Live","",IF($N23="","No stats yet",IF(ReportDate-$N23>7,"Update needed",IF(AND(ISNUMBER($M23),$M23<0.5),"Behind target","OK")))))
A24: Chola MS | B24: Chola MS - SEO & Social Media | C24: Multi-channel | D24: Ayush Jain | I24: Ongoing retainer programme. Target as provided: 38-40 leads and 22 posts (Riya's sheet). | J24: =IF($B24="","",SUMIFS('UPDATE STATS'!$L$5:$L$1004,'UPDATE STATS'!$C$5:$C$1004,$B24)) -> 0 | K24: =IF($B24="","",SUMIFS('UPDATE STATS'!$M$5:$M$1004,'UPDATE STATS'!$C$5:$C$1004,$B24)) -> 0 | L24: =IF($B24="","",SUMIFS('UPDATE STATS'!$J$5:$J$1004,'UPDATE STATS'!$C$5:$C$1004,$B24)) -> 0 | M24: =IF(AND(ISNUMBER($H24),$H24>0,ISNUMBER($J24)),$J24/$H24,"") | N24: =IF($B24="","",IF(COUNTIFS('UPDATE STATS'!$C$5:$C$1004,$B24,'UPDATE STATS'!$A$5:$A$1004,">0")=0,"",_xlfn.MAXIFS('UPDATE STATS'!$A$5:$A$1004,'UPDATE STATS'!$C$5:$C$1004,$B24))) | O24: =IF($B24="","",IF($E24<>"Live","",IF($N24="","No stats yet",IF(ReportDate-$N24>7,"Update needed",IF(AND(ISNUMBER($M24),$M24<0.5),"Behind target","OK")))))
A25: Vestrics | B25: Vestrics - SEO & Social Media | C25: Multi-channel | D25: Ayush Jain | I25: Ongoing retainer programme. | J25: =IF($B25="","",SUMIFS('UPDATE STATS'!$L$5:$L$1004,'UPDATE STATS'!$C$5:$C$1004,$B25)) -> 0 | K25: =IF($B25="","",SUMIFS('UPDATE STATS'!$M$5:$M$1004,'UPDATE STATS'!$C$5:$C$1004,$B25)) -> 0 | L25: =IF($B25="","",SUMIFS('UPDATE STATS'!$J$5:$J$1004,'UPDATE STATS'!$C$5:$C$1004,$B25)) -> 0 | M25: =IF(AND(ISNUMBER($H25),$H25>0,ISNUMBER($J25)),$J25/$H25,"") | N25: =IF($B25="","",IF(COUNTIFS('UPDATE STATS'!$C$5:$C$1004,$B25,'UPDATE STATS'!$A$5:$A$1004,">0")=0,"",_xlfn.MAXIFS('UPDATE STATS'!$A$5:$A$1004,'UPDATE STATS'!$C$5:$C$1004,$B25))) | O25: =IF($B25="","",IF($E25<>"Live","",IF($N25="","No stats yet",IF(ReportDate-$N25>7,"Update needed",IF(AND(ISNUMBER($M25),$M25<0.5),"Behind target","OK")))))
A26: Magnasoft | B26: Magnasoft - SEO & Social Media | C26: Multi-channel | D26: Ayush Jain | I26: Ongoing retainer programme. | J26: =IF($B26="","",SUMIFS('UPDATE STATS'!$L$5:$L$1004,'UPDATE STATS'!$C$5:$C$1004,$B26)) -> 0 | K26: =IF($B26="","",SUMIFS('UPDATE STATS'!$M$5:$M$1004,'UPDATE STATS'!$C$5:$C$1004,$B26)) -> 0 | L26: =IF($B26="","",SUMIFS('UPDATE STATS'!$J$5:$J$1004,'UPDATE STATS'!$C$5:$C$1004,$B26)) -> 0 | M26: =IF(AND(ISNUMBER($H26),$H26>0,ISNUMBER($J26)),$J26/$H26,"") | N26: =IF($B26="","",IF(COUNTIFS('UPDATE STATS'!$C$5:$C$1004,$B26,'UPDATE STATS'!$A$5:$A$1004,">0")=0,"",_xlfn.MAXIFS('UPDATE STATS'!$A$5:$A$1004,'UPDATE STATS'!$C$5:$C$1004,$B26))) | O26: =IF($B26="","",IF($E26<>"Live","",IF($N26="","No stats yet",IF(ReportDate-$N26>7,"Update needed",IF(AND(ISNUMBER($M26),$M26<0.5),"Behind target","OK")))))
A27: Eternelle | B27: Eternelle - SEO & Blogs | C27: Multi-channel | D27: Richi Bagla | I27: Ongoing retainer programme. Target as provided: 6 blogs a month. | J27: =IF($B27="","",SUMIFS('UPDATE STATS'!$L$5:$L$1004,'UPDATE STATS'!$C$5:$C$1004,$B27)) -> 0 | K27: =IF($B27="","",SUMIFS('UPDATE STATS'!$M$5:$M$1004,'UPDATE STATS'!$C$5:$C$1004,$B27)) -> 0 | L27: =IF($B27="","",SUMIFS('UPDATE STATS'!$J$5:$J$1004,'UPDATE STATS'!$C$5:$C$1004,$B27)) -> 0 | M27: =IF(AND(ISNUMBER($H27),$H27>0,ISNUMBER($J27)),$J27/$H27,"") | N27: =IF($B27="","",IF(COUNTIFS('UPDATE STATS'!$C$5:$C$1004,$B27,'UPDATE STATS'!$A$5:$A$1004,">0")=0,"",_xlfn.MAXIFS('UPDATE STATS'!$A$5:$A$1004,'UPDATE STATS'!$C$5:$C$1004,$B27))) | O27: =IF($B27="","",IF($E27<>"Live","",IF($N27="","No stats yet",IF(ReportDate-$N27>7,"Update needed",IF(AND(ISNUMBER($M27),$M27<0.5),"Behind target","OK")))))
A28: Lenovo | B28: Lenovo - Email Deployment | C28: Email | I28: No update provided by team. | J28: =IF($B28="","",SUMIFS('UPDATE STATS'!$L$5:$L$1004,'UPDATE STATS'!$C$5:$C$1004,$B28)) -> 0 | K28: =IF($B28="","",SUMIFS('UPDATE STATS'!$M$5:$M$1004,'UPDATE STATS'!$C$5:$C$1004,$B28)) -> 0 | L28: =IF($B28="","",SUMIFS('UPDATE STATS'!$J$5:$J$1004,'UPDATE STATS'!$C$5:$C$1004,$B28)) -> 0 | M28: =IF(AND(ISNUMBER($H28),$H28>0,ISNUMBER($J28)),$J28/$H28,"") | N28: =IF($B28="","",IF(COUNTIFS('UPDATE STATS'!$C$5:$C$1004,$B28,'UPDATE STATS'!$A$5:$A$1004,">0")=0,"",_xlfn.MAXIFS('UPDATE STATS'!$A$5:$A$1004,'UPDATE STATS'!$C$5:$C$1004,$B28))) | O28: =IF($B28="","",IF($E28<>"Live","",IF($N28="","No stats yet",IF(ReportDate-$N28>7,"Update needed",IF(AND(ISNUMBER($M28),$M28<0.5),"Behind target","OK")))))
A29: Sonalika Tractors | B29: Sonalika Tractors - Meta Automation | C29: Meta Ads | I29: Proposal stage. No update provided yet. | J29: =IF($B29="","",SUMIFS('UPDATE STATS'!$L$5:$L$1004,'UPDATE STATS'!$C$5:$C$1004,$B29)) -> 0 | K29: =IF($B29="","",SUMIFS('UPDATE STATS'!$M$5:$M$1004,'UPDATE STATS'!$C$5:$C$1004,$B29)) -> 0 | L29: =IF($B29="","",SUMIFS('UPDATE STATS'!$J$5:$J$1004,'UPDATE STATS'!$C$5:$C$1004,$B29)) -> 0 | M29: =IF(AND(ISNUMBER($H29),$H29>0,ISNUMBER($J29)),$J29/$H29,"") | N29: =IF($B29="","",IF(COUNTIFS('UPDATE STATS'!$C$5:$C$1004,$B29,'UPDATE STATS'!$A$5:$A$1004,">0")=0,"",_xlfn.MAXIFS('UPDATE STATS'!$A$5:$A$1004,'UPDATE STATS'!$C$5:$C$1004,$B29))) | O29: =IF($B29="","",IF($E29<>"Live","",IF($N29="","No stats yet",IF(ReportDate-$N29>7,"Update needed",IF(AND(ISNUMBER($M29),$M29<0.5),"Behind target","OK")))))
A30: Tata Communications MECCA | B30: Tata MECCA Campaign | C30: Multi-channel | I30: Campaign listed in Team Details (Priyanshu). No other details provided. | J30: =IF($B30="","",SUMIFS('UPDATE STATS'!$L$5:$L$1004,'UPDATE STATS'!$C$5:$C$1004,$B30)) -> 0 | K30: =IF($B30="","",SUMIFS('UPDATE STATS'!$M$5:$M$1004,'UPDATE STATS'!$C$5:$C$1004,$B30)) -> 0 | L30: =IF($B30="","",SUMIFS('UPDATE STATS'!$J$5:$J$1004,'UPDATE STATS'!$C$5:$C$1004,$B30)) -> 0 | M30: =IF(AND(ISNUMBER($H30),$H30>0,ISNUMBER($J30)),$J30/$H30,"") | N30: =IF($B30="","",IF(COUNTIFS('UPDATE STATS'!$C$5:$C$1004,$B30,'UPDATE STATS'!$A$5:$A$1004,">0")=0,"",_xlfn.MAXIFS('UPDATE STATS'!$A$5:$A$1004,'UPDATE STATS'!$C$5:$C$1004,$B30))) | O30: =IF($B30="","",IF($E30<>"Live","",IF($N30="","No stats yet",IF(ReportDate-$N30>7,"Update needed",IF(AND(ISNUMBER($M30),$M30<0.5),"Behind target","OK")))))
J31: =IF($B31="","",SUMIFS('UPDATE STATS'!$L$5:$L$1004,'UPDATE STATS'!$C$5:$C$1004,$B31)) | K31: =IF($B31="","",SUMIFS('UPDATE STATS'!$M$5:$M$1004,'UPDATE STATS'!$C$5:$C$1004,$B31)) | L31: =IF($B31="","",SUMIFS('UPDATE STATS'!$J$5:$J$1004,'UPDATE STATS'!$C$5:$C$1004,$B31)) | M31: =IF(AND(ISNUMBER($H31),$H31>0,ISNUMBER($J31)),$J31/$H31,"") | N31: =IF($B31="","",IF(COUNTIFS('UPDATE STATS'!$C$5:$C$1004,$B31,'UPDATE STATS'!$A$5:$A$1004,">0")=0,"",_xlfn.MAXIFS('UPDATE STATS'!$A$5:$A$1004,'UPDATE STATS'!$C$5:$C$1004,$B31))) | O31: =IF($B31="","",IF($E31<>"Live","",IF($N31="","No stats yet",IF(ReportDate-$N31>7,"Update needed",IF(AND(ISNUMBER($M31),$M31<0.5),"Behind target","OK")))))
